Workbook

Sheet ブランド別サマリー
A1: POS売上 予算・前年対比（2026年10月度／前年同月 2025年10月）
A2: ブランド系統別の集計（店舗別明細シートの小計を参照）
A4: ブランド系統 | B4: 店舗数 | C4: 売上金額 | D4: 売上構成比 | E4: 予算金額 | F4: 予算達成率 | G4: 予算差額 | H4: 前年売上金額 | I4: 前年対比 | J4: 前年差額
A5: アルチビオ | B5: 11 | C5: =店舗別明細!E16 -> 8874005 | D5: =IF($C$9=0,"-",C5/$C$9) -> 0.358959 | E5: =店舗別明細!F16 -> 42800000 | F5: =IF(E5=0,"-",C5/E5) -> 0.20733657 | G5: =C5-E5 -> -33925995 | H5: =店舗別明細!I16 -> 38987668 | I5: =IF(H5=0,"-",C5/H5) -> 0.22761056 | J5: =C5-H5 -> -30113663
A6: スタジオピッコーネ／ピッコーネクラブ | B6: 23 | C6: =店舗別明細!E40 -> 11150262 | D6: =IF($C$9=0,"-",C6/$C$9) -> 0.45103501 | E6: =店舗別明細!F40 -> 85888000 | F6: =IF(E6=0,"-",C6/E6) -> 0.12982328 | G6: =C6-E6 -> -74737738 | H6: =店舗別明細!I40 -> 78268222 | I6: =IF(H6=0,"-",C6/H6) -> 0.14246219 | J6: =C6-H6 -> -67117960
A7: ピッコーネ | B7: 4 | C7: =店舗別明細!E45 -> 1026732 | D7: =IF($C$9=0,"-",C7/$C$9) -> 0.041531946 | E7: =店舗別明細!F45 -> 11700000 | F7: =IF(E7=0,"-",C7/E7) -> 0.087754872 | G7: =C7-E7 -> -10673268 | H7: =店舗別明細!I45 -> 12271253 | I7: =IF(H7=0,"-",C7/H7) -> 0.083669695 | J7: =C7-H7 -> -11244521
A8: 複合（アルチビオ＋ピッコーネ系） | B8: 5 | C8: =店舗別明細!E51 -> 3670501 | D8: =IF($C$9=0,"-",C8/$C$9) -> 0.14847404 | E8: =店舗別明細!F51 -> 24321000 | F8: =IF(E8=0,"-",C8/E8) -> 0.150919 | G8: =C8-E8 -> -20650499 | H8: =店舗別明細!I51 -> 20612405 | I8: =IF(H8=0,"-",C8/H8) -> 0.17807243 | J8: =C8-H8 -> -16941904
A9: 合計 | B9: =SUM(B5:B8) -> 43 | C9: =SUM(C5:C8) -> 24721500 | D9: =IF($C$9=0,"-",C9/$C$9) -> 1 | E9: =SUM(E5:E8) -> 164709000 | F9: =IF(E9=0,"-",C9/E9) -> 0.15009198 | G9: =C9-E9 -> -139987500 | H9: =SUM(H5:H8) -> 150139548 | I9: =IF(H9=0,"-",C9/H9) -> 0.16465682 | J9: =C9-H9 -> -125418048
A11: ※ 前年対比には前年実績なしの大宮高島屋（スタジオピッコーネ系）の売上も含む。
A12: ※ 複合 = アルチビオとピッコーネ系を1コードで計上している売場（内訳不明）。

Sheet 店舗別明細
A1: POS売上 予算・前年対比（2026年10月度／前年同月 2025年10月）
A2: ブランド系統ごとに店舗をまとめ、各系統内は予算達成率の高い順。達成率・差額・前年比は数式で計算。
A4: ブランド系統 | B4: 店舗コード | C4: 施設・店舗名 | D4: 取扱ブランド（元データ表記） | E4: 売上金額 | F4: 予算金額 | G4: 予算達成率 | H4: 予算差額 | I4: 前年売上金額 | J4: 前年対比 | K4: 前年差額
A5: アルチビオ | B5: 32673900 | C5: 高島屋高崎店 | D5: アルチビオ | E5: 897774 | F5: 1200000 | G5: =IF(F5=0,"-",E5/F5) -> 0.748145 | H5: =E5-F5 -> -302226 | I5: 1184930 | J5: =IF(I5=0,"前年実績なし",E5/I5) -> 0.75765995 | K5: =E5-I5 -> -287156
A6: アルチビオ | B6: 32580400 | C6: ハービスPLAZA店 | D6: アルチビオ | E6: 1942301 | F6: 3812000 | G6: =IF(F6=0,"-",E6/F6) -> 0.50952282 | H6: =E6-F6 -> -1869699 | I6: 3514950 | J6: =IF(I6=0,"前年実績なし",E6/I6) -> 0.55258282 | K6: =E6-I6 -> -1572649
A7: アルチビオ | B7: 32670600 | C7: 高島屋新宿店 | D7: アルチビオ | E7: 1202200 | F7: 3958000 | G7: =IF(F7=0,"-",E7/F7) -> 0.30373926 | H7: =E7-F7 -> -2755800 | I7: 3803490 | J7: =IF(I7=0,"前年実績なし",E7/I7) -> 0.31607813 | K7: =E7-I7 -> -2601290
A8: アルチビオ | B8: 32674900 | C8: 松屋銀座本店 | D8: アルチビオ | E8: 856826 | F8: 2900000 | G8: =IF(F8=0,"-",E8/F8) -> 0.29545724 | H8: =E8-F8 -> -2043174 | I8: 2769045 | J8: =IF(I8=0,"前年実績なし",E8/I8) -> 0.30943015 | K8: =E8-I8 -> -1912219
A9: アルチビオ | B9: 32570100 | C9: 高島屋大阪店 | D9: アルチビオ | E9: 1650946 | F9: 6591000 | G9: =IF(F9=0,"-",E9/F9) -> 0.2504849 | H9: =E9-F9 -> -4940054 | I9: 4992300 | J9: =IF(I9=0,"前年実績なし",E9/I9) -> 0.33069848 | K9: =E9-I9 -> -3341354
A10: アルチビオ | B10: 32581000 | C10: 堀江店 | D10: アルチビオ | E10: 898194 | F10: 4782000 | G10: =IF(F10=0,"-",E10/F10) -> 0.18782811 | H10: =E10-F10 -> -3883806 | I10: 4451408 | J10: =IF(I10=0,"前年実績なし",E10/I10) -> 0.20177751 | K10: =E10-I10 -> -3553214
A11: アルチビオ | B11: 32673800 | C11: 高島屋横浜店 | D11: アルチビオ | E11: 371528 | F11: 2180000 | G11: =IF(F11=0,"-",E11/F11) -> 0.17042569 | H11: =E11-F11 -> -1808472 | I11: 1807900 | J11: =IF(I11=0,"前年実績なし",E11/I11) -> 0.20550252 | K11: =E11-I11 -> -1436372
A12: アルチビオ | B12: 32674400 | C12: 伊勢丹浦和店 | D12: アルチビオ | E12: 212253 | F12: 1470000 | G12: =IF(F12=0,"-",E12/F12) -> 0.1443898 | H12: =E12-F12 -> -1257747 | I12: 1293200 | J12: =IF(I12=0,"前年実績なし",E12/I12) -> 0.16413006 | K12: =E12-I12 -> -1080947
A13: アルチビオ | B13: 32673500 | C13: 日本橋三越本店 | D13: アルチビオ | E13: 526863 | F13: 4457000 | G13: =IF(F13=0,"-",E13/F13) -> 0.11821023 | H13: =E13-F13 -> -3930137 | I13: 4363100 | J13: =IF(I13=0,"前年実績なし",E13/I13) -> 0.12075428 | K13: =E13-I13 -> -3836237
A14: アルチビオ | B14: 32680600 | C14: 那須ガーデンアウトレット店 | D14: アルチビオ | E14: 132320 | F14: 3050000 | G14: =IF(F14=0,"-",E14/F14) -> 0.043383607 | H14: =E14-F14 -> -2917680 | I14: 2677580 | J14: =IF(I14=0,"前年実績なし",E14/I14) -> 0.049417758 | K14: =E14-I14 -> -2545260
A15: アルチビオ | B15: 32571600 | C15: ジェイアール名古屋タカシマヤ店 | D15: アルチビオ | E15: 182800 | F15: 8400000 | G15: =IF(F15=0,"-",E15/F15) -> 0.021761905 | H15: =E15-F15 -> -8217200 | I15: 8129765 | J15: =IF(I15=0,"前年実績なし",E15/I15) -> 0.022485275 | K15: =E15-I15 -> -7946965
A16: アルチビオ 小計（11店舗） | E16: =SUBTOTAL(9,E5:E15) -> 8874005 | F16: =SUBTOTAL(9,F5:F15) -> 42800000 | G16: =IF(F16=0,"-",E16/F16) -> 0.20733657 | H16: =E16-F16 -> -33925995 | I16: =SUBTOTAL(9,I5:I15) -> 38987668 | J16: =IF(I16=0,"-",E16/I16) -> 0.22761056 | K16: =E16-I16 -> -30113663
A17: スタジオピッコーネ／ピッコーネクラブ | B17: 32570200 | C17: 高島屋大阪店 | D17: スタジオピッコーネ・ピッコーネクラブ | E17: 1262854 | F17: 5370000 | G17: =IF(F17=0,"-",E17/F17) -> 0.23516834 | H17: =E17-F17 -> -4107146 | I17: 4965460 | J17: =IF(I17=0,"前年実績なし",E17/I17) -> 0.2543277 | K17: =E17-I17 -> -3702606
A18: スタジオピッコーネ／ピッコーネクラブ | B18: 32676200 | C18: 東武宇都宮百貨店 | D18: スタジオピッコーネ・ピッコーネクラブ | E18: 419700 | F18: 2100000 | G18: =IF(F18=0,"-",E18/F18) -> 0.19985714 | H18: =E18-F18 -> -1680300 | I18: 1953490 | J18: =IF(I18=0,"前年実績なし",E18/I18) -> 0.21484625 | K18: =E18-I18 -> -1533790
A19: スタジオピッコーネ／ピッコーネクラブ | B19: 32574100 | C19: 広島三越店 | D19: スタジオピッコーネ | E19: 507400 | F19: 2600000 | G19: =IF(F19=0,"-",E19/F19) -> 0.19515385 | H19: =E19-F19 -> -2092600 | I19: 1796500 | J19: =IF(I19=0,"前年実績なし",E19/I19) -> 0.28243807 | K19: =E19-I19 -> -1289100
A20: スタジオピッコーネ／ピッコーネクラブ | B20: 32675700 | C20: 静岡伊勢丹 | D20: スタジオピッコーネ・ピッコーネクラブ | E20: 241380 | F20: 1250000 | G20: =IF(F20=0,"-",E20/F20) -> 0.193104 | H20: =E20-F20 -> -1008620 | I20: 997950 | J20: =IF(I20=0,"前年実績なし",E20/I20) -> 0.24187585 | K20: =E20-I20 -> -756570
A21: スタジオピッコーネ／ピッコーネクラブ | B21: 32670400 | C21: 高島屋高崎店 | D21: スタジオピッコーネ・ピッコーネクラブ | E21: 776168 | F21: 4050000 | G21: =IF(F21=0,"-",E21/F21) -> 0.19164642 | H21: =E21-F21 -> -3273832 | I21: 3884330 | J21: =IF(I21=0,"前年実績なし",E21/I21) -> 0.1998203 | K21: =E21-I21 -> -3108162
A22: スタジオピッコーネ／ピッコーネクラブ | B22: 32572600 | C22: 大丸福岡天神店 | D22: スタジオピッコーネ・ピッコーネクラブ | E22: 521900 | F22: 2830000 | G22: =IF(F22=0,"-",E22/F22) -> 0.18441696 | H22: =E22-F22 -> -2308100 | I22: 2230000 | J22: =IF(I22=0,"前年実績なし",E22/I22) -> 0.23403587 | K22: =E22-I22 -> -1708100
A23: スタジオピッコーネ／ピッコーネクラブ | B23: 32670200 | C23: 高島屋横浜店 | D23: スタジオピッコーネ・ピッコーネクラブ | E23: 920100 | F23: 5100000 | G23: =IF(F23=0,"-",E23/F23) -> 0.18041176 | H23: =E23-F23 -> -4179900 | I23: 4342490 | J23: =IF(I23=0,"前年実績なし",E23/I23) -> 0.21188304 | K23: =E23-I23 -> -3422390
A24: スタジオピッコーネ／ピッコーネクラブ | B24: 32573700 | C24: 近鉄百貨店上本町店 | D24: スタジオピッコーネ・ピッコーネクラブ | E24: 691454 | F24: 3940000 | G24: =IF(F24=0,"-",E24/F24) -> 0.17549594 | H24: =E24-F24 -> -3248546 | I24: 3597695 | J24: =IF(I24=0,"前年実績なし",E24/I24) -> 0.19219361 | K24: =E24-I24 -> -2906241
A25: スタジオピッコーネ／ピッコーネクラブ | B25: 32575700 | C25: 名古屋三越栄店 | D25: スタジオピッコーネ | E25: 721272 | F25: 4200000 | G25: =IF(F25=0,"-",E25/F25) -> 0.17173143 | H25: =E25-F25 -> -3478728 | I25: 4050580 | J25: =IF(I25=0,"前年実績なし",E25/I25) -> 0.17806635 | K25: =E25-I25 -> -3329308
A26: スタジオピッコーネ／ピッコーネクラブ | B26: 32671900 | C26: 松坂屋上野店 | D26: スタジオピッコーネ・ピッコーネクラブ | E26: 492100 | F26: 2900000 | G26: =IF(F26=0,"-",E26/F26) -> 0.16968966 | H26: =E26-F26 -> -2407900 | I26: 2327950 | J26: =IF(I26=0,"前年実績なし",E26/I26) -> 0.2113877 | K26: =E26-I26 -> -1835850
A27: スタジオピッコーネ／ピッコーネクラブ | B27: 32675800 | C27: 伊勢丹立川店 | D27: スタジオピッコーネ・ピッコーネクラブ | E27: 414000 | F27: 2650000 | G27: =IF(F27=0,"-",E27/F27) -> 0.15622642 | H27: =E27-F27 -> -2236000 | I27: 2438700 | J27: =IF(I27=0,"前年実績なし",E27/I27) -> 0.16976258 | K27: =E27-I27 -> -2024700
A28: スタジオピッコーネ／ピッコーネクラブ | B28: 32573400 | C28: 近鉄百貨店和歌山店 | D28: スタジオピッコーネ・ピッコーネクラブ | E28: 315700 | F28: 2280000 | G28: =IF(F28=0,"-",E28/F28) -> 0.13846491 | H28: =E28-F28 -> -1964300 | I28: 2014530 | J28: =IF(I28=0,"前年実績なし",E28/I28) -> 0.15671149 | K28: =E28-I28 -> -1698830
... A39: スタジオピッコーネ／ピッコーネクラブ | B39: 32676300 | C39: 高島屋新宿店 | D39: スタジオピッコーネ・ピッコーネクラブ | E39: 127300 | F39: 4900000 | G39: =IF(F39=0,"-",E39/F39) -> 0.025979592 | H39: =E39-F39 -> -4772700 | I39: 4882220 | J39: =IF(I39=0,"前年実績なし",E39/I39) -> 0.026074204 | K39: =E39-I39 -> -4754920
A40: スタジオピッコーネ／ピッコーネクラブ 小計（23店舗） | E40: =SUBTOTAL(9,E17:E39) -> 11150262 | F40: =SUBTOTAL(9,F17:F39) -> 85888000 | G40: =IF(F40=0,"-",E40/F40) -> 0.12982328 | H40: =E40-F40 -> -74737738 | I40: =SUBTOTAL(9,I17:I39) -> 78268222 | J40: =IF(I40=0,"-",E40/I40) -> 0.14246219 | K40: =E40-I40 -> -67117960
A41: ピッコーネ | B41: 32675100 | C41: 東急百貨店たまプラーザ店 | D41: ピッコーネ | E41: 413000 | F41: 3650000 | G41: =IF(F41=0,"-",E41/F41) -> 0.11315068 | H41: =E41-F41 -> -3237000 | I41: 3418600 | J41: =IF(I41=0,"前年実績なし",E41/I41) -> 0.12080969 | K41: =E41-I41 -> -3005600
A42: ピッコーネ | B42: 32580700 | C42: ホテルニューオータニ大阪店 | D42: ピッコーネ | E42: 147316 | F42: 1520000 | G42: =IF(F42=0,"-",E42/F42) -> 0.096918421 | H42: =E42-F42 -> -1372684 | I42: 1451810 | J42: =IF(I42=0,"前年実績なし",E42/I42) -> 0.10147058 | K42: =E42-I42 -> -1304494
A43: ピッコーネ | B43: 32580600 | C43: ラポルテ芦屋店 | D43: ピッコーネ | E43: 263871 | F43: 3130000 | G43: =IF(F43=0,"-",E43/F43) -> 0.084303834 | H43: =E43-F43 -> -2866129 | I43: 2850123 | J43: =IF(I43=0,"前年実績なし",E43/I43) -> 0.09258232 | K43: =E43-I43 -> -2586252
A44: ピッコーネ | B44: 32675300 | C44: 東急百貨店吉祥寺店 | D44: ピッコーネ | E44: 202545 | F44: 3400000 | G44: =IF(F44=0,"-",E44/F44) -> 0.059572059 | H44: =E44-F44 -> -3197455 | I44: 4550720 | J44: =IF(I44=0,"前年実績なし",E44/I44) -> 0.044508342 | K44: =E44-I44 -> -4348175
A45: ピッコーネ 小計（4店舗） | E45: =SUBTOTAL(9,E41:E44) -> 1026732 | F45: =SUBTOTAL(9,F41:F44) -> 11700000 | G45: =IF(F45=0,"-",E45/F45) -> 0.087754872 | H45: =E45-F45 -> -10673268 | I45: =SUBTOTAL(9,I41:I44) -> 12271253 | J45: =IF(I45=0,"-",E45/I45) -> 0.083669695 | K45: =E45-I45 -> -11244521
A46: 複合（アルチビオ＋ピッコーネ系） | B46: 32671500 | C46: 札幌三越 | D46: ピッコーネ・アルチビオ | E46: 922530 | F46: 3079000 | G46: =IF(F46=0,"-",E46/F46) -> 0.29962001 | H46: =E46-F46 -> -2156470 | I46: 2912300 | J46: =IF(I46=0,"前年実績なし",E46/I46) -> 0.31677025 | K46: =E46-I46 -> -1989770
A47: 複合（アルチビオ＋ピッコーネ系） | B47: 32572200 | C47: 松坂屋名古屋店 | D47: アルチビオ・ピッコーネクラブ | E47: 1582708 | F47: 9500000 | G47: =IF(F47=0,"-",E47/F47) -> 0.16660084 | H47: =E47-F47 -> -7917292 | I47: 9277415 | J47: =IF(I47=0,"前年実績なし",E47/I47) -> 0.17059795 | K47: =E47-I47 -> -7694707
A48: 複合（アルチビオ＋ピッコーネ系） | B48: 32570800 | C48: 高島屋京都店 | D48: アルチビオ・ピッコーネクラブ | E48: 597712 | F48: 4687000 | G48: =IF(F48=0,"-",E48/F48) -> 0.1275255 | H48: =E48-F48 -> -4089288 | I48: 3376895 | J48: =IF(I48=0,"前年実績なし",E48/I48) -> 0.17700047 | K48: =E48-I48 -> -2779183
A49: 複合（アルチビオ＋ピッコーネ系） | B49: 32573300 | C49: あべのハルカス近鉄本店 | D49: アルチビオ・ピッコ（元データで名称途切れ） | E49: 247325 | F49: 2883000 | G49: =IF(F49=0,"-",E49/F49) -> 0.085787374 | H49: =E49-F49 -> -2635675 | I49: 2232420 | J49: =IF(I49=0,"前年実績なし",E49/I49) -> 0.11078784 | K49: =E49-I49 -> -1985095
A50: 複合（アルチビオ＋ピッコーネ系） | B50: 32570700 | C50: 西宮阪急店 | D50: ピッコーネクラブ・アルチビオ | E50: 320226 | F50: 4172000 | G50: =IF(F50=0,"-",E50/F50) -> 0.076755992 | H50: =E50-F50 -> -3851774 | I50: 2813375 | J50: =IF(I50=0,"前年実績なし",E50/I50) -> 0.11382272 | K50: =E50-I50 -> -2493149
A51: 複合（アルチビオ＋ピッコーネ系） 小計（5店舗） | E51: =SUBTOTAL(9,E46:E50) -> 3670501 | F51: =SUBTOTAL(9,F46:F50) -> 24321000 | G51: =IF(F51=0,"-",E51/F51) -> 0.150919 | H51: =E51-F51 -> -20650499 | I51: =SUBTOTAL(9,I46:I50) -> 20612405 | J51: =IF(I51=0,"-",E51/I51) -> 0.17807243 | K51: =E51-I51 -> -16941904
...

Sheet 施設別
A1: POS売上 予算・前年対比（2026年10月度／前年同月 2025年10月）
A2: 同じ施設に複数ブランドが入っている場合に1行にまとめた集計（売上の大きい順）。各値は店舗別明細からSUMIFSで集計。
A4: 施設・店舗名 | B4: アルチビオ | C4: スタジオピッコーネ／ピッコーネクラブ | D4: ピッコーネ | E4: 複合 （アルチビオ＋ピッコーネ系） | F4: 売上合計 | G4: 予算合計 | H4: 予算達成率 | I4: 前年売上合計 | J4: 前年対比
A5: 高島屋大阪店 | B5: =SUMIFS(店舗別明細!$E$5:$E$51,店舗別明細!$C$5:$C$51,$A5,店舗別明細!$A$5:$A$51,"アルチビオ") -> 1650946 | C5: =SUMIFS(店舗別明細!$E$5:$E$51,店舗別明細!$C$5:$C$51,$A5,店舗別明細!$A$5:$A$51,"スタジオピッコーネ／ピッコーネクラブ") -> 1262854 | D5: =SUMIFS(店舗別明細!$E$5:$E$51,店舗別明細!$C$5:$C$51,$A5,店舗別明細!$A$5:$A$51,"ピッコーネ") -> 0 | E5: =SUMIFS(店舗別明細!$E$5:$E$51,店舗別明細!$C$5:$C$51,$A5,店舗別明細!$A$5:$A$51,"複合（アルチビオ＋ピッコーネ系）") -> 0 | F5: =SUM(B5:E5) -> 2913800 | G5: =SUMIFS(店舗別明細!$F$5:$F$51,店舗別明細!$C$5:$C$51,$A5) -> 11961000 | H5: =IF(G5=0,"-",F5/G5) -> 0.24360839 | I5: =SUMIFS(店舗別明細!$I$5:$I$51,店舗別明細!$C$5:$C$51,$A5) -> 9957760 | J5: =IF(I5=0,"前年実績なし",F5/I5) -> 0.29261601
A6: ハービスPLAZA店 | B6: =SUMIFS(店舗別明細!$E$5:$E$51,店舗別明細!$C$5:$C$51,$A6,店舗別明細!$A$5:$A$51,"アルチビオ") -> 1942301 | C6: =SUMIFS(店舗別明細!$E$5:$E$51,店舗別明細!$C$5:$C$51,$A6,店舗別明細!$A$5:$A$51,"スタジオピッコーネ／ピッコーネクラブ") -> 0 | D6: =SUMIFS(店舗別明細!$E$5:$E$51,店舗別明細!$C$5:$C$51,$A6,店舗別明細!$A$5:$A$51,"ピッコーネ") -> 0 | E6: =SUMIFS(店舗別明細!$E$5:$E$51,店舗別明細!$C$5:$C$51,$A6,店舗別明細!$A$5:$A$51,"複合（アルチビオ＋ピッコーネ系）") -> 0 | F6: =SUM(B6:E6) -> 1942301 | G6: =SUMIFS(店舗別明細!$F$5:$F$51,店舗別明細!$C$5:$C$51,$A6) -> 3812000 | H6: =IF(G6=0,"-",F6/G6) -> 0.50952282 | I6: =SUMIFS(店舗別明細!$I$5:$I$51,店舗別明細!$C$5:$C$51,$A6) -> 3514950 | J6: =IF(I6=0,"前年実績なし",F6/I6) -> 0.55258282
A7: 高島屋高崎店 | B7: =SUMIFS(店舗別明細!$E$5:$E$51,店舗別明細!$C$5:$C$51,$A7,店舗別明細!$A$5:$A$51,"アルチビオ") -> 897774 | C7: =SUMIFS(店舗別明細!$E$5:$E$51,店舗別明細!$C$5:$C$51,$A7,店舗別明細!$A$5:$A$51,"スタジオピッコーネ／ピッコーネクラブ") -> 776168 | D7: =SUMIFS(店舗別明細!$E$5:$E$51,店舗別明細!$C$5:$C$51,$A7,店舗別明細!$A$5:$A$51,"ピッコーネ") -> 0 | E7: =SUMIFS(店舗別明細!$E$5:$E$51,店舗別明細!$C$5:$C$51,$A7,店舗別明細!$A$5:$A$51,"複合（アルチビオ＋ピッコーネ系）") -> 0 | F7: =SUM(B7:E7) -> 1673942 | G7: =SUMIFS(店舗別明細!$F$5:$F$51,店舗別明細!$C$5:$C$51,$A7) -> 5250000 | H7: =IF(G7=0,"-",F7/G7) -> 0.3188461 | I7: =SUMIFS(店舗別明細!$I$5:$I$51,店舗別明細!$C$5:$C$51,$A7) -> 5069260 | J7: =IF(I7=0,"前年実績なし",F7/I7) -> 0.33021427
A8: 松坂屋名古屋店 | B8: =SUMIFS(店舗別明細!$E$5:$E$51,店舗別明細!$C$5:$C$51,$A8,店舗別明細!$A$5:$A$51,"アルチビオ") -> 0 | C8: =SUMIFS(店舗別明細!$E$5:$E$51,店舗別明細!$C$5:$C$51,$A8,店舗別明細!$A$5:$A$51,"スタジオピッコーネ／ピッコーネクラブ") -> 0 | D8: =SUMIFS(店舗別明細!$E$5:$E$51,店舗別明細!$C$5:$C$51,$A8,店舗別明細!$A$5:$A$51,"ピッコーネ") -> 0 | E8: =SUMIFS(店舗別明細!$E$5:$E$51,店舗別明細!$C$5:$C$51,$A8,店舗別明細!$A$5:$A$51,"複合（アルチビオ＋ピッコーネ系）") -> 1582708 | F8: =SUM(B8:E8) -> 1582708 | G8: =SUMIFS(店舗別明細!$F$5:$F$51,店舗別明細!$C$5:$C$51,$A8) -> 9500000 | H8: =IF(G8=0,"-",F8/G8) -> 0.16660084 | I8: =SUMIFS(店舗別明細!$I$5:$I$51,店舗別明細!$C$5:$C$51,$A8) -> 9277415 | J8: =IF(I8=0,"前年実績なし",F8/I8) -> 0.17059795
A9: 高島屋新宿店 | B9: =SUMIFS(店舗別明細!$E$5:$E$51,店舗別明細!$C$5:$C$51,$A9,店舗別明細!$A$5:$A$51,"アルチビオ") -> 1202200 | C9: =SUMIFS(店舗別明細!$E$5:$E$51,店舗別明細!$C$5:$C$51,$A9,店舗別明細!$A$5:$A$51,"スタジオピッコーネ／ピッコーネクラブ") -> 127300 | D9: =SUMIFS(店舗別明細!$E$5:$E$51,店舗別明細!$C$5:$C$51,$A9,店舗別明細!$A$5:$A$51,"ピッコーネ") -> 0 | E9: =SUMIFS(店舗別明細!$E$5:$E$51,店舗別明細!$C$5:$C$51,$A9,店舗別明細!$A$5:$A$51,"複合（アルチビオ＋ピッコーネ系）") -> 0 | F9: =SUM(B9:E9) -> 1329500 | G9: =SUMIFS(店舗別明細!$F$5:$F$51,店舗別明細!$C$5:$C$51,$A9) -> 8858000 | H9: =IF(G9=0,"-",F9/G9) -> 0.15009031 | I9: =SUMIFS(店舗別明細!$I$5:$I$51,店舗別明細!$C$5:$C$51,$A9) -> 8685710 | J9: =IF(I9=0,"前年実績なし",F9/I9) -> 0.15306751
A10: 高島屋横浜店 | B10: =SUMIFS(店舗別明細!$E$5:$E$51,店舗別明細!$C$5:$C$51,$A10,店舗別明細!$A$5:$A$51,"アルチビオ") -> 371528 | C10: =SUMIFS(店舗別明細!$E$5:$E$51,店舗別明細!$C$5:$C$51,$A10,店舗別明細!$A$5:$A$51,"スタジオピッコーネ／ピッコーネクラブ") -> 920100 | D10: =SUMIFS(店舗別明細!$E$5:$E$51,店舗別明細!$C$5:$C$51,$A10,店舗別明細!$A$5:$A$51,"ピッコーネ") -> 0 | E10: =SUMIFS(店舗別明細!$E$5:$E$51,店舗別明細!$C$5:$C$51,$A10,店舗別明細!$A$5:$A$51,"複合（アルチビオ＋ピッコーネ系）") -> 0 | F10: =SUM(B10:E10) -> 1291628 | G10: =SUMIFS(店舗別明細!$F$5:$F$51,店舗別明細!$C$5:$C$51,$A10) -> 7280000 | H10: =IF(G10=0,"-",F10/G10) -> 0.17742143 | I10: =SUMIFS(店舗別明細!$I$5:$I$51,店舗別明細!$C$5:$C$51,$A10) -> 6150390 | J10: =IF(I10=0,"前年実績なし",F10/I10) -> 0.2100075
A11: 松屋銀座本店 | B11: =SUMIFS(店舗別明細!$E$5:$E$51,店舗別明細!$C$5:$C$51,$A11,店舗別明細!$A$5:$A$51,"アルチビオ") -> 856826 | C11: =SUMIFS(店舗別明細!$E$5:$E$51,店舗別明細!$C$5:$C$51,$A11,店舗別明細!$A$5:$A$51,"スタジオピッコーネ／ピッコーネクラブ") -> 312500 | D11: =SUMIFS(店舗別明細!$E$5:$E$51,店舗別明細!$C$5:$C$51,$A11,店舗別明細!$A$5:$A$51,"ピッコーネ") -> 0 | E11: =SUMIFS(店舗別明細!$E$5:$E$51,店舗別明細!$C$5:$C$51,$A11,店舗別明細!$A$5:$A$51,"複合（アルチビオ＋ピッコーネ系）") -> 0 | F11: =SUM(B11:E11) -> 1169326 | G11: =SUMIFS(店舗別明細!$F$5:$F$51,店舗別明細!$C$5:$C$51,$A11) -> 6000000 | H11: =IF(G11=0,"-",F11/G11) -> 0.19488767 | I11: =SUMIFS(店舗別明細!$I$5:$I$51,店舗別明細!$C$5:$C$51,$A11) -> 5692657 | J11: =IF(I11=0,"前年実績なし",F11/I11) -> 0.20540953
A12: 日本橋三越本店 | B12: =SUMIFS(店舗別明細!$E$5:$E$51,店舗別明細!$C$5:$C$51,$A12,店舗別明細!$A$5:$A$51,"アルチビオ") -> 526863 | C12: =SUMIFS(店舗別明細!$E$5:$E$51,店舗別明細!$C$5:$C$51,$A12,店舗別明細!$A$5:$A$51,"スタジオピッコーネ／ピッコーネクラブ") -> 619544 | D12: =SUMIFS(店舗別明細!$E$5:$E$51,店舗別明細!$C$5:$C$51,$A12,店舗別明細!$A$5:$A$51,"ピッコーネ") -> 0 | E12: =SUMIFS(店舗別明細!$E$5:$E$51,店舗別明細!$C$5:$C$51,$A12,店舗別明細!$A$5:$A$51,"複合（アルチビオ＋ピッコーネ系）") -> 0 | F12: =SUM(B12:E12) -> 1146407 | G12: =SUMIFS(店舗別明細!$F$5:$F$51,店舗別明細!$C$5:$C$51,$A12) -> 16457000 | H12: =IF(G12=0,"-",F12/G12) -> 0.069660752 | I12: =SUMIFS(店舗別明細!$I$5:$I$51,店舗別明細!$C$5:$C$51,$A12) -> 16128200 | J12: =IF(I12=0,"前年実績なし",F12/I12) -> 0.071080902
A13: 札幌三越 | B13: =SUMIFS(店舗別明細!$E$5:$E$51,店舗別明細!$C$5:$C$51,$A13,店舗別明細!$A$5:$A$51,"アルチビオ") -> 0 | C13: =SUMIFS(店舗別明細!$E$5:$E$51,店舗別明細!$C$5:$C$51,$A13,店舗別明細!$A$5:$A$51,"スタジオピッコーネ／ピッコーネクラブ") -> 0 | D13: =SUMIFS(店舗別明細!$E$5:$E$51,店舗別明細!$C$5:$C$51,$A13,店舗別明細!$A$5:$A$51,"ピッコーネ") -> 0 | E13: =SUMIFS(店舗別明細!$E$5:$E$51,店舗別明細!$C$5:$C$51,$A13,店舗別明細!$A$5:$A$51,"複合（アルチビオ＋ピッコーネ系）") -> 922530 | F13: =SUM(B13:E13) -> 922530 | G13: =SUMIFS(店舗別明細!$F$5:$F$51,店舗別明細!$C$5:$C$51,$A13) -> 3079000 | H13: =IF(G13=0,"-",F13/G13) -> 0.29962001 | I13: =SUMIFS(店舗別明細!$I$5:$I$51,店舗別明細!$C$5:$C$51,$A13) -> 2912300 | J13: =IF(I13=0,"前年実績なし",F13/I13) -> 0.31677025
A14: 堀江店 | B14: =SUMIFS(店舗別明細!$E$5:$E$51,店舗別明細!$C$5:$C$51,$A14,店舗別明細!$A$5:$A$51,"アルチビオ") -> 898194 | C14: =SUMIFS(店舗別明細!$E$5:$E$51,店舗別明細!$C$5:$C$51,$A14,店舗別明細!$A$5:$A$51,"スタジオピッコーネ／ピッコーネクラブ") -> 0 | D14: =SUMIFS(店舗別明細!$E$5:$E$51,店舗別明細!$C$5:$C$51,$A14,店舗別明細!$A$5:$A$51,"ピッコーネ") -> 0 | E14: =SUMIFS(店舗別明細!$E$5:$E$51,店舗別明細!$C$5:$C$51,$A14,店舗別明細!$A$5:$A$51,"複合（アルチビオ＋ピッコーネ系）") -> 0 | F14: =SUM(B14:E14) -> 898194 | G14: =SUMIFS(店舗別明細!$F$5:$F$51,店舗別明細!$C$5:$C$51,$A14) -> 4782000 | H14: =IF(G14=0,"-",F14/G14) -> 0.18782811 | I14: =SUMIFS(店舗別明細!$I$5:$I$51,店舗別明細!$C$5:$C$51,$A14) -> 4451408 | J14: =IF(I14=0,"前年実績なし",F14/I14) -> 0.20177751
A15: あべのハルカス近鉄本店 | B15: =SUMIFS(店舗別明細!$E$5:$E$51,店舗別明細!$C$5:$C$51,$A15,店舗別明細!$A$5:$A$51,"アルチビオ") -> 0 | C15: =SUMIFS(店舗別明細!$E$5:$E$51,店舗別明細!$C$5:$C$51,$A15,店舗別明細!$A$5:$A$51,"スタジオピッコーネ／ピッコーネクラブ") -> 506300 | D15: =SUMIFS(店舗別明細!$E$5:$E$51,店舗別明細!$C$5:$C$51,$A15,店舗別明細!$A$5:$A$51,"ピッコーネ") -> 0 | E15: =SUMIFS(店舗別明細!$E$5:$E$51,店舗別明細!$C$5:$C$51,$A15,店舗別明細!$A$5:$A$51,"複合（アルチビオ＋ピッコーネ系）") -> 247325 | F15: =SUM(B15:E15) -> 753625 | G15: =SUMIFS(店舗別明細!$F$5:$F$51,店舗別明細!$C$5:$C$51,$A15) -> 7283000 | H15: =IF(G15=0,"-",F15/G15) -> 0.10347728 | I15: =SUMIFS(店舗別明細!$I$5:$I$51,店舗別明細!$C$5:$C$51,$A15) -> 6391565 | J15: =IF(I15=0,"前年実績なし",F15/I15) -> 0.11790931
A16: 名古屋三越栄店 | B16: =SUMIFS(店舗別明細!$E$5:$E$51,店舗別明細!$C$5:$C$51,$A16,店舗別明細!$A$5:$A$51,"アルチビオ") -> 0 | C16: =SUMIFS(店舗別明細!$E$5:$E$51,店舗別明細!$C$5:$C$51,$A16,店舗別明細!$A$5:$A$51,"スタジオピッコーネ／ピッコーネクラブ") -> 721272 | D16: =SUMIFS(店舗別明細!$E$5:$E$51,店舗別明細!$C$5:$C$51,$A16,店舗別明細!$A$5:$A$51,"ピッコーネ") -> 0 | E16: =SUMIFS(店舗別明細!$E$5:$E$51,店舗別明細!$C$5:$C$51,$A16,店舗別明細!$A$5:$A$51,"複合（アルチビオ＋ピッコーネ系）") -> 0 | F16: =SUM(B16:E16) -> 721272 | G16: =SUMIFS(店舗別明細!$F$5:$F$51,店舗別明細!$C$5:$C$51,$A16) -> 4200000 | H16: =IF(G16=0,"-",F16/G16) -> 0.17173143 | I16: =SUMIFS(店舗別明細!$I$5:$I$51,店舗別明細!$C$5:$C$51,$A16) -> 4050580 | J16: =IF(I16=0,"前年実績なし",F16/I16) -> 0.17806635
... A40: 高島屋大宮店 | B40: =SUMIFS(店舗別明細!$E$5:$E$51,店舗別明細!$C$5:$C$51,$A40,店舗別明細!$A$5:$A$51,"アルチビオ") -> 0 | C40: =SUMIFS(店舗別明細!$E$5:$E$51,店舗別明細!$C$5:$C$51,$A40,店舗別明細!$A$5:$A$51,"スタジオピッコーネ／ピッコーネクラブ") -> 119200 | D40: =SUMIFS(店舗別明細!$E$5:$E$51,店舗別明細!$C$5:$C$51,$A40,店舗別明細!$A$5:$A$51,"ピッコーネ") -> 0 | E40: =SUMIFS(店舗別明細!$E$5:$E$51,店舗別明細!$C$5:$C$51,$A40,店舗別明細!$A$5:$A$51,"複合（アルチビオ＋ピッコーネ系）") -> 0 | F40: =SUM(B40:E40) -> 119200 | G40: =SUMIFS(店舗別明細!$F$5:$F$51,店舗別明細!$C$5:$C$51,$A40) -> 1700000 | H40: =IF(G40=0,"-",F40/G40) -> 0.070117647 | I40: =SUMIFS(店舗別明細!$I$5:$I$51,店舗別明細!$C$5:$C$51,$A40) -> 0 | J40: =IF(I40=0,"前年実績なし",F40/I40) -> 前年実績なし
A41: 合計（36施設） | B41: =SUM(B5:B40) -> 8874005 | C41: =SUM(C5:C40) -> 11150262 | D41: =SUM(D5:D40) -> 1026732 | E41: =SUM(E5:E40) -> 3670501 | F41: =SUM(F5:F40) -> 24721500 | G41: =SUM(G5:G40) -> 164709000 | H41: =IF(G41=0,"-",F41/G41) -> 0.15009198 | I41: =SUM(I5:I40) -> 150139548 | J41: =IF(I41=0,"-",F41/I41) -> 0.16465682
A43: ※ 太字の施設は複数ブランド（複数店舗コード）を持つ施設。ブランド列の「-」は該当ブランドなし。

Sheet 元データ
A1: 店舗 | B1: 指定月 【前年同月 2025/10】 | I1: 詳細
B2: 売上金額 | C2: 予算情報及び対比 | F2: 前年同月情報及び対比
C3: 予算金額 | D3: 達成率 | E3: 差額 | F3: 前年売上金額 | G3: 前年対比 | H3: 前年差額
A4: (32673900)高島屋高崎店アルチビオ | B4: 897774 | C4: 1200000 | D4: 74.8 | E4: -302226 | F4: 1184930 | G4: 75.8 | H4: -287156
A5: (32580400)ハービスPLAZA店アルチビオ | B5: 1942301 | C5: 3812000 | D5: 51 | E5: -1869699 | F5: 3514950 | G5: 55.3 | H5: -1572649
A6: (32670600)高島屋新宿店アルチビオ | B6: 1202200 | C6: 3958000 | D6: 30.4 | E6: -2755800 | F6: 3803490 | G6: 31.6 | H6: -2601290
A7: (32671500)札幌三越ピッコーネ・アルチビオ | B7: 922530 | C7: 3079000 | D7: 30 | E7: -2156470 | F7: 2912300 | G7: 31.7 | H7: -1989770
A8: (32674900)松屋銀座本店アルチビオ | B8: 856826 | C8: 2900000 | D8: 29.5 | E8: -2043174 | F8: 2769045 | G8: 30.9 | H8: -1912219
A9: (32570100)高島屋大阪店アルチビオ | B9: 1650946 | C9: 6591000 | D9: 25 | E9: -4940054 | F9: 4992300 | G9: 33.1 | H9: -3341354
A10: (32570200)高島屋大阪店ｽﾀｼﾞｵﾋﾟｯｺｰﾈ・ﾋﾟｯｺｰﾈｸﾗﾌﾞ | B10: 1262854 | C10: 5370000 | D10: 23.5 | E10: -4107146 | F10: 4965460 | G10: 25.4 | H10: -3702606
A11: (32676200)東武宇都宮百貨店ｽﾀｼﾞｵﾋﾟｯｺｰﾈ・ﾋﾟｯｺｰﾈｸﾗﾌﾞ | B11: 419700 | C11: 2100000 | D11: 20 | E11: -1680300 | F11: 1953490 | G11: 21.5 | H11: -1533790
A12: (32574100)広島三越店スタジオピッコーネ | B12: 507400 | C12: 2600000 | D12: 19.5 | E12: -2092600 | F12: 1796500 | G12: 28.2 | H12: -1289100
A13: (32675700)静岡伊勢丹ｽﾀｼﾞｵﾋﾟｯｺｰﾈ・ﾋﾟｯｺｰﾈｸﾗﾌﾞ | B13: 241380 | C13: 1250000 | D13: 19.3 | E13: -1008620 | F13: 997950 | G13: 24.2 | H13: -756570
A14: (32670400)高島屋高崎店ｽﾀｼﾞｵﾋﾟｯｺｰﾈ・ﾋﾟｯｺｰﾈｸﾗﾌﾞ | B14: 776168 | C14: 4050000 | D14: 19.2 | E14: -3273832 | F14: 3884330 | G14: 20 | H14: -3108162
A15: (32581000)堀江店アルチビオ | B15: 898194 | C15: 4782000 | D15: 18.8 | E15: -3883806 | F15: 4451408 | G15: 20.2 | H15: -3553214
... A47: 合計 | B47: 24721500 | C47: 164709000 | D47: 15 | E47: -139987500 | F47: 150139548 | G47: 16.5 | H47: -125418048
