Workbook

Sheet ブランド別サマリー
A1: =取込チェック!$H$3 -> POS売上 予算・前年対比（2026年9月度／前年同月 2025年9月）
A2: ブランド系統別の集計。3つの元データシートを貼り替えると全シートが自動更新されます。
A3: ■ PB合計（予算・前年対比）
A4: ブランド系統 | B4: 店舗数 | C4: 売上金額 | D4: 売上構成比 | E4: 予算金額 | F4: 予算達成率 | G4: 予算差額 | H4: 前年売上金額 | I4: 前年対比 | J4: 前年差額
A5: アルチビオ | B5: =COUNTIFS(店舗マスタ!$E$5:$E$304,$A5,店舗マスタ!$F$5:$F$304,1) -> 11 | C5: =SUMIFS(店舗マスタ!$G$5:$G$304,店舗マスタ!$E$5:$E$304,$A5) -> 21514701 | D5: =IF($C$9=0,"-",C5/$C$9) -> 0.19534312 | E5: =SUMIFS(店舗マスタ!$H$5:$H$304,店舗マスタ!$E$5:$E$304,$A5) -> 26854000 | F5: =IF(E5=0,"-",C5/E5) -> 0.80117305 | G5: =C5-E5 -> -5339299 | H5: =SUMIFS(店舗マスタ!$I$5:$I$304,店舗マスタ!$E$5:$E$304,$A5) -> 24125211 | I5: =IF(H5=0,"-",C5/H5) -> 0.89179328 | J5: =C5-H5 -> -2610510
A6: スタジオピッコーネ／ピッコーネクラブ | B6: =COUNTIFS(店舗マスタ!$E$5:$E$304,$A6,店舗マスタ!$F$5:$F$304,1) -> 23 | C6: =SUMIFS(店舗マスタ!$G$5:$G$304,店舗マスタ!$E$5:$E$304,$A6) -> 58463370 | D6: =IF($C$9=0,"-",C6/$C$9) -> 0.53081923 | E6: =SUMIFS(店舗マスタ!$H$5:$H$304,店舗マスタ!$E$5:$E$304,$A6) -> 71383000 | F6: =IF(E6=0,"-",C6/E6) -> 0.81900971 | G6: =C6-E6 -> -12919630 | H6: =SUMIFS(店舗マスタ!$I$5:$I$304,店舗マスタ!$E$5:$E$304,$A6) -> 59754000 | I6: =IF(H6=0,"-",C6/H6) -> 0.97840094 | J6: =C6-H6 -> -1290630
A7: ピッコーネ | B7: =COUNTIFS(店舗マスタ!$E$5:$E$304,$A7,店舗マスタ!$F$5:$F$304,1) -> 5 | C7: =SUMIFS(店舗マスタ!$G$5:$G$304,店舗マスタ!$E$5:$E$304,$A7) -> 16191756 | D7: =IF($C$9=0,"-",C7/$C$9) -> 0.14701334 | E7: =SUMIFS(店舗マスタ!$H$5:$H$304,店舗マスタ!$E$5:$E$304,$A7) -> 15550000 | F7: =IF(E7=0,"-",C7/E7) -> 1.0412705 | G7: =C7-E7 -> 641756 | H7: =SUMIFS(店舗マスタ!$I$5:$I$304,店舗マスタ!$E$5:$E$304,$A7) -> 13628859 | I7: =IF(H7=0,"-",C7/H7) -> 1.1880493 | J7: =C7-H7 -> 2562897
A8: 複合（アルチビオ＋ピッコーネ系） | B8: =COUNTIFS(店舗マスタ!$E$5:$E$304,$A8,店舗マスタ!$F$5:$F$304,1) -> 5 | C8: =SUMIFS(店舗マスタ!$G$5:$G$304,店舗マスタ!$E$5:$E$304,$A8) -> 13968177 | D8: =IF($C$9=0,"-",C8/$C$9) -> 0.12682432 | E8: =SUMIFS(店舗マスタ!$H$5:$H$304,店舗マスタ!$E$5:$E$304,$A8) -> 17840000 | F8: =IF(E8=0,"-",C8/E8) -> 0.78296956 | G8: =C8-E8 -> -3871823 | H8: =SUMIFS(店舗マスタ!$I$5:$I$304,店舗マスタ!$E$5:$E$304,$A8) -> 14941710 | I8: =IF(H8=0,"-",C8/H8) -> 0.93484461 | J8: =C8-H8 -> -973533
A9: 合計 | B9: =SUM(B5:B8) -> 44 | C9: =SUM(C5:C8) -> 110138004 | D9: =IF($C$9=0,"-",C9/$C$9) -> 1 | E9: =SUM(E5:E8) -> 131627000 | F9: =IF(E9=0,"-",C9/E9) -> 0.83674325 | G9: =C9-E9 -> -21488996 | H9: =SUM(H5:H8) -> 112449780 | I9: =IF(H9=0,"-",C9/H9) -> 0.9794417 | J9: =C9-H9 -> -2311776
A11: ■ PB内訳（P：プロパー／B：バーゲン）
A12: ブランド系統 | B12: PB合計売上 | C12: P売上 | D12: B売上 | E12: B比率 | F12: PB前年売上 | G12: P前年売上 | H12: B前年売上 | I12: P前年対比 | J12: B前年対比
A13: =A5 -> アルチビオ | B13: =C5 -> 21514701 | C13: =IF(取込チェック!$K$3=0,"",SUMIFS(店舗マスタ!$P$5:$P$304,店舗マスタ!$E$5:$E$304,$A13)) -> 16221041 | D13: =IF(C13="","",B13-C13) -> 5293660 | E13: =IF(D13="","",IF(B13=0,"-",D13/B13)) -> 0.2460485 | F13: =H5 -> 24125211 | G13: =IF(取込チェック!$K$3=0,"",SUMIFS(店舗マスタ!$Q$5:$Q$304,店舗マスタ!$E$5:$E$304,$A13)) -> 18543471 | H13: =IF(G13="","",F13-G13) -> 5581740 | I13: =IF(C13="","",IF(G13=0,"-",C13/G13)) -> 0.87475754 | J13: =IF(D13="","",IF(H13=0,"-",D13/H13)) -> 0.94838885
A14: =A6 -> スタジオピッコーネ／ピッコーネクラブ | B14: =C6 -> 58463370 | C14: =IF(取込チェック!$K$3=0,"",SUMIFS(店舗マスタ!$P$5:$P$304,店舗マスタ!$E$5:$E$304,$A14)) -> 54359840 | D14: =IF(C14="","",B14-C14) -> 4103530 | E14: =IF(D14="","",IF(B14=0,"-",D14/B14)) -> 0.070189762 | F14: =H6 -> 59754000 | G14: =IF(取込チェック!$K$3=0,"",SUMIFS(店舗マスタ!$Q$5:$Q$304,店舗マスタ!$E$5:$E$304,$A14)) -> 56165000 | H14: =IF(G14="","",F14-G14) -> 3589000 | I14: =IF(C14="","",IF(G14=0,"-",C14/G14)) -> 0.9678597 | J14: =IF(D14="","",IF(H14=0,"-",D14/H14)) -> 1.1433631
A15: =A7 -> ピッコーネ | B15: =C7 -> 16191756 | C15: =IF(取込チェック!$K$3=0,"",SUMIFS(店舗マスタ!$P$5:$P$304,店舗マスタ!$E$5:$E$304,$A15)) -> 7486916 | D15: =IF(C15="","",B15-C15) -> 8704840 | E15: =IF(D15="","",IF(B15=0,"-",D15/B15)) -> 0.53760939 | F15: =H7 -> 13628859 | G15: =IF(取込チェック!$K$3=0,"",SUMIFS(店舗マスタ!$Q$5:$Q$304,店舗マスタ!$E$5:$E$304,$A15)) -> 10704513 | H15: =IF(G15="","",F15-G15) -> 2924346 | I15: =IF(C15="","",IF(G15=0,"-",C15/G15)) -> 0.69941678 | J15: =IF(D15="","",IF(H15=0,"-",D15/H15)) -> 2.9766792
A16: =A8 -> 複合（アルチビオ＋ピッコーネ系） | B16: =C8 -> 13968177 | C16: =IF(取込チェック!$K$3=0,"",SUMIFS(店舗マスタ!$P$5:$P$304,店舗マスタ!$E$5:$E$304,$A16)) -> 10146817 | D16: =IF(C16="","",B16-C16) -> 3821360 | E16: =IF(D16="","",IF(B16=0,"-",D16/B16)) -> 0.27357614 | F16: =H8 -> 14941710 | G16: =IF(取込チェック!$K$3=0,"",SUMIFS(店舗マスタ!$Q$5:$Q$304,店舗マスタ!$E$5:$E$304,$A16)) -> 12040710 | H16: =IF(G16="","",F16-G16) -> 2901000 | I16: =IF(C16="","",IF(G16=0,"-",C16/G16)) -> 0.84270919 | J16: =IF(D16="","",IF(H16=0,"-",D16/H16)) -> 1.3172561
A17: 合計 | B17: =SUM(B13:B16) -> 110138004 | C17: =IF(取込チェック!$K$3=0,"",SUM(C13:C16)) -> 88214614 | D17: =IF(C17="","",B17-C17) -> 21923390 | E17: =IF(D17="","",IF(B17=0,"-",D17/B17)) -> 0.19905382 | F17: =SUM(F13:F16) -> 112449780 | G17: =IF(取込チェック!$K$3=0,"",SUM(G13:G16)) -> 97453694 | H17: =IF(G17="","",F17-G17) -> 14996086 | I17: =IF(C17="","",IF(G17=0,"-",C17/G17)) -> 0.90519518 | J17: =IF(D17="","",IF(H17=0,"-",D17/H17)) -> 1.4619408
A19: ■ データ取込チェック | F19: ■ 毎月の更新手順
A20: PB合計：元データ合計行 − 本表（0ならOK） | B20: =IFERROR(IFERROR(INDEX(元データ_PB合計!$B:$B,MATCH("合計",元データ_PB合計!$A:$A,0)),"合計行なし")-C9,"合計行なし") -> 0 | F20: ① POSCMの出力ファイル（PB合計・P・Bの3シート）を開く
A21: P：元データ合計行 − 本表（0ならOK） | B21: =IF(取込チェック!$K$3=0,"未貼付",IFERROR(IFERROR(INDEX(元データ_P!$B:$B,MATCH("合計",元データ_P!$A:$A,0)),"合計行なし")-C17,"合計行なし")) -> 0 | F21: ② 「PB合計」シートで全選択コピー（Ctrl+A → Ctrl+C）
A22: B：元データ合計行 − 本表（0ならOK） | B22: =IF(取込チェック!$K$3=0,"未貼付",IFERROR(IFERROR(INDEX(元データ_B!$B:$B,MATCH("合計",元データ_B!$A:$A,0)),"合計行なし")-D17,"合計行なし")) -> 0 | F22: ③ このファイルの「元データ_PB合計」を全選択して削除し、A1に貼り付け
A23: 3シートの対象月が一致 | B23: =IF(取込チェック!$K$3=0,"未貼付",IF(AND(元データ_PB合計!$B$1=元データ_P!$B$1,元データ_PB合計!$B$1=元データ_B!$B$1),"OK","不一致：貼り付けた月を確認")) -> OK | F23: ④ 同様に「P」→「元データ_P」、「B」→「元データ_B」に貼り付け
A24: 未登録の店舗数（0ならOK） | B24: =COUNTIF(取込チェック!$G$6:$G$505,"未登録*")+COUNTIF(取込チェック!$N$6:$N$505,"未登録*")+COUNTIF(取込チェック!$U$6:$U$505,"未登録*") -> 0 | F24: ⑤ 「総合判定」がOKなら完了（タイトルの年月も自動更新）
A25: 明細シートの予備枠 | B25: =IF(OR(B5>14,B6>26,B7>8,B8>8),"不足：明細の枠を追加してください","OK") -> OK | F25: ⑥ 「未登録」が出たら、取込チェックの赤い行を見て店舗マスタに追加
A26: 総合判定 | B26: =IF(AND(N(B20)=0,ISNUMBER(B20),OR(B21="未貼付",B21=0),OR(B22="未貼付",B22=0),OR(B23="OK",B23="未貼付"),B24=0,B25="OK"),IF(取込チェック!$K$3=0,"OK（PB合計のみ。P/B未貼付）","OK：集計は元データと一致しています"),"要確認：上の項目と取込チェックシートを確認") -> OK：集計は元データと一致しています | F26: ※ 元データシートの名前は変えないでください。
A27: （参考）マスタ登録済で今月データなしの店舗数 | B27: =COUNTIFS(店舗マスタ!$B$5:$B$304,"<>",店舗マスタ!$F$5:$F$304,0) -> 0 | F27: ※ PB合計だけ貼った場合も、PB内訳以外は更新されます。
A28: （参考）Bシートにない前年B売上（PB−Pで補完） | B28: =IF(取込チェック!$K$3=0,"-",H17-IFERROR(INDEX(元データ_B!$F:$F,MATCH("合計",元データ_B!$A:$A,0)),0)) -> 668100

Sheet PB内訳
A1: =取込チェック!$H$3&" PB内訳" -> POS売上 予算・前年対比（2026年9月度／前年同月 2025年9月） PB内訳
A2: PB合計 = P（プロパー）＋ B（バーゲン）。B = PB合計 − P で計算。予算はPB合計に対する予算のみ（P・B別の予算は元データになし）。ブランド系統ごとに店舗コード順。
A4: 店舗 | D4: 当月売上 | H4: 予算（PB合計） | J4: 前年売上 | M4: 前年対比
A5: ブランド系統 | B5: 店舗コード | C5: 施設・店舗名 | D5: PB合計 | E5: P（プロパー） | F5: B（バーゲン） | G5: B比率 | H5: 予算金額 | I5: PB達成率 | J5: PB合計 | K5: P（プロパー） | L5: B（バーゲン） | M5: PB合計 | N5: P（プロパー） | O5: B（バーゲン）
A6: =IF($B6="","","アルチビオ") -> アルチビオ | B6: =IFERROR(INDEX(店舗マスタ!$B$5:$B$304,MATCH("アルチビオ|1",店舗マスタ!$L$5:$L$304,0)),"") -> 32570100 | C6: =IF($B6="","",INDEX(店舗マスタ!$C$5:$C$304,MATCH($B6,店舗マスタ!$B$5:$B$304,0))) -> 高島屋大阪店 | D6: =IF($B6="","",INDEX(店舗マスタ!$G$5:$G$304,MATCH($B6,店舗マスタ!$B$5:$B$304,0))) -> 2048565 | E6: =IF($B6="","",INDEX(店舗マスタ!$P$5:$P$304,MATCH($B6,店舗マスタ!$B$5:$B$304,0))) -> 1959835 | F6: =IF($B6="","",INDEX(店舗マスタ!$R$5:$R$304,MATCH($B6,店舗マスタ!$B$5:$B$304,0))) -> 88730 | G6: =IF(OR($B6="",F6=""),"",IF(D6=0,"-",F6/D6)) -> 0.043313246 | H6: =IF($B6="","",INDEX(店舗マスタ!$H$5:$H$304,MATCH($B6,店舗マスタ!$B$5:$B$304,0))) -> 2150000 | I6: =IF($B6="","",IF(H6=0,"-",D6/H6)) -> 0.95282093 | J6: =IF($B6="","",INDEX(店舗マスタ!$I$5:$I$304,MATCH($B6,店舗マスタ!$B$5:$B$304,0))) -> 2098500 | K6: =IF($B6="","",INDEX(店舗マスタ!$Q$5:$Q$304,MATCH($B6,店舗マスタ!$B$5:$B$304,0))) -> 1916000 | L6: =IF($B6="","",INDEX(店舗マスタ!$S$5:$S$304,MATCH($B6,店舗マスタ!$B$5:$B$304,0))) -> 182500 | M6: =IF(OR($B6="",D6=""),"",IF(N(J6)=0,"前年なし",D6/J6)) -> 0.97620443 | N6: =IF(OR($B6="",E6=""),"",IF(N(K6)=0,"前年なし",E6/K6)) -> 1.0228784 | O6: =IF(OR($B6="",F6=""),"",IF(N(L6)=0,"前年なし",F6/L6)) -> 0.48619178
A7: =IF($B7="","","アルチビオ") -> アルチビオ | B7: =IFERROR(INDEX(店舗マスタ!$B$5:$B$304,MATCH("アルチビオ|2",店舗マスタ!$L$5:$L$304,0)),"") -> 32571600 | C7: =IF($B7="","",INDEX(店舗マスタ!$C$5:$C$304,MATCH($B7,店舗マスタ!$B$5:$B$304,0))) -> ジェイアール名古屋タカシマヤ店 | D7: =IF($B7="","",INDEX(店舗マスタ!$G$5:$G$304,MATCH($B7,店舗マスタ!$B$5:$B$304,0))) -> 3250690 | E7: =IF($B7="","",INDEX(店舗マスタ!$P$5:$P$304,MATCH($B7,店舗マスタ!$B$5:$B$304,0))) -> 2783500 | F7: =IF($B7="","",INDEX(店舗マスタ!$R$5:$R$304,MATCH($B7,店舗マスタ!$B$5:$B$304,0))) -> 467190 | G7: =IF(OR($B7="",F7=""),"",IF(D7=0,"-",F7/D7)) -> 0.14372026 | H7: =IF($B7="","",INDEX(店舗マスタ!$H$5:$H$304,MATCH($B7,店舗マスタ!$B$5:$B$304,0))) -> 3681000 | I7: =IF($B7="","",IF(H7=0,"-",D7/H7)) -> 0.8830997 | J7: =IF($B7="","",INDEX(店舗マスタ!$I$5:$I$304,MATCH($B7,店舗マスタ!$B$5:$B$304,0))) -> 3216380 | K7: =IF($B7="","",INDEX(店舗マスタ!$Q$5:$Q$304,MATCH($B7,店舗マスタ!$B$5:$B$304,0))) -> 3003000 | L7: =IF($B7="","",INDEX(店舗マスタ!$S$5:$S$304,MATCH($B7,店舗マスタ!$B$5:$B$304,0))) -> 213380 | M7: =IF(OR($B7="",D7=""),"",IF(N(J7)=0,"前年なし",D7/J7)) -> 1.0106673 | N7: =IF(OR($B7="",E7=""),"",IF(N(K7)=0,"前年なし",E7/K7)) -> 0.92690643 | O7: =IF(OR($B7="",F7=""),"",IF(N(L7)=0,"前年なし",F7/L7)) -> 2.1894742
A8: =IF($B8="","","アルチビオ") -> アルチビオ | B8: =IFERROR(INDEX(店舗マスタ!$B$5:$B$304,MATCH("アルチビオ|3",店舗マスタ!$L$5:$L$304,0)),"") -> 32580400 | C8: =IF($B8="","",INDEX(店舗マスタ!$C$5:$C$304,MATCH($B8,店舗マスタ!$B$5:$B$304,0))) -> ハービスPLAZA店 | D8: =IF($B8="","",INDEX(店舗マスタ!$G$5:$G$304,MATCH($B8,店舗マスタ!$B$5:$B$304,0))) -> 2922845 | E8: =IF($B8="","",INDEX(店舗マスタ!$P$5:$P$304,MATCH($B8,店舗マスタ!$B$5:$B$304,0))) -> 1946845 | F8: =IF($B8="","",INDEX(店舗マスタ!$R$5:$R$304,MATCH($B8,店舗マスタ!$B$5:$B$304,0))) -> 976000 | G8: =IF(OR($B8="",F8=""),"",IF(D8=0,"-",F8/D8)) -> 0.33392123 | H8: =IF($B8="","",INDEX(店舗マスタ!$H$5:$H$304,MATCH($B8,店舗マスタ!$B$5:$B$304,0))) -> 3613000 | I8: =IF($B8="","",IF(H8=0,"-",D8/H8)) -> 0.80898007 | J8: =IF($B8="","",INDEX(店舗マスタ!$I$5:$I$304,MATCH($B8,店舗マスタ!$B$5:$B$304,0))) -> 3478940 | K8: =IF($B8="","",INDEX(店舗マスタ!$Q$5:$Q$304,MATCH($B8,店舗マスタ!$B$5:$B$304,0))) -> 1717190 | L8: =IF($B8="","",INDEX(店舗マスタ!$S$5:$S$304,MATCH($B8,店舗マスタ!$B$5:$B$304,0))) -> 1761750 | M8: =IF(OR($B8="",D8=""),"",IF(N(J8)=0,"前年なし",D8/J8)) -> 0.8401539 | N8: =IF(OR($B8="",E8=""),"",IF(N(K8)=0,"前年なし",E8/K8)) -> 1.1337388 | O8: =IF(OR($B8="",F8=""),"",IF(N(L8)=0,"前年なし",F8/L8)) -> 0.55399461
A9: =IF($B9="","","アルチビオ") -> アルチビオ | B9: =IFERROR(INDEX(店舗マスタ!$B$5:$B$304,MATCH("アルチビオ|4",店舗マスタ!$L$5:$L$304,0)),"") -> 32581000 | C9: =IF($B9="","",INDEX(店舗マスタ!$C$5:$C$304,MATCH($B9,店舗マスタ!$B$5:$B$304,0))) -> 堀江店 | D9: =IF($B9="","",INDEX(店舗マスタ!$G$5:$G$304,MATCH($B9,店舗マスタ!$B$5:$B$304,0))) -> 1572240 | E9: =IF($B9="","",INDEX(店舗マスタ!$P$5:$P$304,MATCH($B9,店舗マスタ!$B$5:$B$304,0))) -> 659140 | F9: =IF($B9="","",INDEX(店舗マスタ!$R$5:$R$304,MATCH($B9,店舗マスタ!$B$5:$B$304,0))) -> 913100 | G9: =IF(OR($B9="",F9=""),"",IF(D9=0,"-",F9/D9)) -> 0.58076375 | H9: =IF($B9="","",INDEX(店舗マスタ!$H$5:$H$304,MATCH($B9,店舗マスタ!$B$5:$B$304,0))) -> 2787000 | I9: =IF($B9="","",IF(H9=0,"-",D9/H9)) -> 0.56413348 | J9: =IF($B9="","",INDEX(店舗マスタ!$I$5:$I$304,MATCH($B9,店舗マスタ!$B$5:$B$304,0))) -> 2688196 | K9: =IF($B9="","",INDEX(店舗マスタ!$Q$5:$Q$304,MATCH($B9,店舗マスタ!$B$5:$B$304,0))) -> 1676126 | L9: =IF($B9="","",INDEX(店舗マスタ!$S$5:$S$304,MATCH($B9,店舗マスタ!$B$5:$B$304,0))) -> 1012070 | M9: =IF(OR($B9="",D9=""),"",IF(N(J9)=0,"前年なし",D9/J9)) -> 0.58486807 | N9: =IF(OR($B9="",E9=""),"",IF(N(K9)=0,"前年なし",E9/K9)) -> 0.39325206 | O9: =IF(OR($B9="",F9=""),"",IF(N(L9)=0,"前年なし",F9/L9)) -> 0.90221032
A10: =IF($B10="","","アルチビオ") -> アルチビオ | B10: =IFERROR(INDEX(店舗マスタ!$B$5:$B$304,MATCH("アルチビオ|5",店舗マスタ!$L$5:$L$304,0)),"") -> 32670600 | C10: =IF($B10="","",INDEX(店舗マスタ!$C$5:$C$304,MATCH($B10,店舗マスタ!$B$5:$B$304,0))) -> 高島屋新宿店 | D10: =IF($B10="","",INDEX(店舗マスタ!$G$5:$G$304,MATCH($B10,店舗マスタ!$B$5:$B$304,0))) -> 2991974 | E10: =IF($B10="","",INDEX(店舗マスタ!$P$5:$P$304,MATCH($B10,店舗マスタ!$B$5:$B$304,0))) -> 2613574 | F10: =IF($B10="","",INDEX(店舗マスタ!$R$5:$R$304,MATCH($B10,店舗マスタ!$B$5:$B$304,0))) -> 378400 | G10: =IF(OR($B10="",F10=""),"",IF(D10=0,"-",F10/D10)) -> 0.12647169 | H10: =IF($B10="","",INDEX(店舗マスタ!$H$5:$H$304,MATCH($B10,店舗マスタ!$B$5:$B$304,0))) -> 2571000 | I10: =IF($B10="","",IF(H10=0,"-",D10/H10)) -> 1.1637394 | J10: =IF($B10="","",INDEX(店舗マスタ!$I$5:$I$304,MATCH($B10,店舗マスタ!$B$5:$B$304,0))) -> 2496485 | K10: =IF($B10="","",INDEX(店舗マスタ!$Q$5:$Q$304,MATCH($B10,店舗マスタ!$B$5:$B$304,0))) -> 2460585 | L10: =IF($B10="","",INDEX(店舗マスタ!$S$5:$S$304,MATCH($B10,店舗マスタ!$B$5:$B$304,0))) -> 35900 | M10: =IF(OR($B10="",D10=""),"",IF(N(J10)=0,"前年なし",D10/J10)) -> 1.1984747 | N10: =IF(OR($B10="",E10=""),"",IF(N(K10)=0,"前年なし",E10/K10)) -> 1.0621759 | O10: =IF(OR($B10="",F10=""),"",IF(N(L10)=0,"前年なし",F10/L10)) -> 10.54039
A11: =IF($B11="","","アルチビオ") -> アルチビオ | B11: =IFERROR(INDEX(店舗マスタ!$B$5:$B$304,MATCH("アルチビオ|6",店舗マスタ!$L$5:$L$304,0)),"") -> 32673500 | C11: =IF($B11="","",INDEX(店舗マスタ!$C$5:$C$304,MATCH($B11,店舗マスタ!$B$5:$B$304,0))) -> 日本橋三越本店 | D11: =IF($B11="","",INDEX(店舗マスタ!$G$5:$G$304,MATCH($B11,店舗マスタ!$B$5:$B$304,0))) -> 3069240 | E11: =IF($B11="","",INDEX(店舗マスタ!$P$5:$P$304,MATCH($B11,店舗マスタ!$B$5:$B$304,0))) -> 2845200 | F11: =IF($B11="","",INDEX(店舗マスタ!$R$5:$R$304,MATCH($B11,店舗マスタ!$B$5:$B$304,0))) -> 224040 | G11: =IF(OR($B11="",F11=""),"",IF(D11=0,"-",F11/D11)) -> 0.072995269 | H11: =IF($B11="","",INDEX(店舗マスタ!$H$5:$H$304,MATCH($B11,店舗マスタ!$B$5:$B$304,0))) -> 2691000 | I11: =IF($B11="","",IF(H11=0,"-",D11/H11)) -> 1.1405574 | J11: =IF($B11="","",INDEX(店舗マスタ!$I$5:$I$304,MATCH($B11,店舗マスタ!$B$5:$B$304,0))) -> 2647100 | K11: =IF($B11="","",INDEX(店舗マスタ!$Q$5:$Q$304,MATCH($B11,店舗マスタ!$B$5:$B$304,0))) -> 2619200 | L11: =IF($B11="","",INDEX(店舗マスタ!$S$5:$S$304,MATCH($B11,店舗マスタ!$B$5:$B$304,0))) -> 27900 | M11: =IF(OR($B11="",D11=""),"",IF(N(J11)=0,"前年なし",D11/J11)) -> 1.1594726 | N11: =IF(OR($B11="",E11=""),"",IF(N(K11)=0,"前年なし",E11/K11)) -> 1.0862859 | O11: =IF(OR($B11="",F11=""),"",IF(N(L11)=0,"前年なし",F11/L11)) -> 8.0301075
A12: =IF($B12="","","アルチビオ") -> アルチビオ | B12: =IFERROR(INDEX(店舗マスタ!$B$5:$B$304,MATCH("アルチビオ|7",店舗マスタ!$L$5:$L$304,0)),"") -> 32673800 | C12: =IF($B12="","",INDEX(店舗マスタ!$C$5:$C$304,MATCH($B12,店舗マスタ!$B$5:$B$304,0))) -> 高島屋横浜店 | D12: =IF($B12="","",INDEX(店舗マスタ!$G$5:$G$304,MATCH($B12,店舗マスタ!$B$5:$B$304,0))) -> 1579789 | E12: =IF($B12="","",INDEX(店舗マスタ!$P$5:$P$304,MATCH($B12,店舗マスタ!$B$5:$B$304,0))) -> 1123189 | F12: =IF($B12="","",INDEX(店舗マスタ!$R$5:$R$304,MATCH($B12,店舗マスタ!$B$5:$B$304,0))) -> 456600 | G12: =IF(OR($B12="",F12=""),"",IF(D12=0,"-",F12/D12)) -> 0.28902594 | H12: =IF($B12="","",INDEX(店舗マスタ!$H$5:$H$304,MATCH($B12,店舗マスタ!$B$5:$B$304,0))) -> 1900000 | I12: =IF($B12="","",IF(H12=0,"-",D12/H12)) -> 0.83146789 | J12: =IF($B12="","",INDEX(店舗マスタ!$I$5:$I$304,MATCH($B12,店舗マスタ!$B$5:$B$304,0))) -> 1483030 | K12: =IF($B12="","",INDEX(店舗マスタ!$Q$5:$Q$304,MATCH($B12,店舗マスタ!$B$5:$B$304,0))) -> 1314530 | L12: =IF($B12="","",INDEX(店舗マスタ!$S$5:$S$304,MATCH($B12,店舗マスタ!$B$5:$B$304,0))) -> 168500 | M12: =IF(OR($B12="",D12=""),"",IF(N(J12)=0,"前年なし",D12/J12)) -> 1.0652441 | N12: =IF(OR($B12="",E12=""),"",IF(N(K12)=0,"前年なし",E12/K12)) -> 0.85444151 | O12: =IF(OR($B12="",F12=""),"",IF(N(L12)=0,"前年なし",F12/L12)) -> 2.7097923
A13: =IF($B13="","","アルチビオ") -> アルチビオ | B13: =IFERROR(INDEX(店舗マスタ!$B$5:$B$304,MATCH("アルチビオ|8",店舗マスタ!$L$5:$L$304,0)),"") -> 32673900 | C13: =IF($B13="","",INDEX(店舗マスタ!$C$5:$C$304,MATCH($B13,店舗マスタ!$B$5:$B$304,0))) -> 高島屋高崎店 | D13: =IF($B13="","",INDEX(店舗マスタ!$G$5:$G$304,MATCH($B13,店舗マスタ!$B$5:$B$304,0))) -> 1117980 | E13: =IF($B13="","",INDEX(店舗マスタ!$P$5:$P$304,MATCH($B13,店舗マスタ!$B$5:$B$304,0))) -> 880280 | F13: =IF($B13="","",INDEX(店舗マスタ!$R$5:$R$304,MATCH($B13,店舗マスタ!$B$5:$B$304,0))) -> 237700 | G13: =IF(OR($B13="",F13=""),"",IF(D13=0,"-",F13/D13)) -> 0.21261561 | H13: =IF($B13="","",INDEX(店舗マスタ!$H$5:$H$304,MATCH($B13,店舗マスタ!$B$5:$B$304,0))) -> 1249000 | I13: =IF($B13="","",IF(H13=0,"-",D13/H13)) -> 0.89510008 | J13: =IF($B13="","",INDEX(店舗マスタ!$I$5:$I$304,MATCH($B13,店舗マスタ!$B$5:$B$304,0))) -> 1132140 | K13: =IF($B13="","",INDEX(店舗マスタ!$Q$5:$Q$304,MATCH($B13,店舗マスタ!$B$5:$B$304,0))) -> 994940 | L13: =IF($B13="","",INDEX(店舗マスタ!$S$5:$S$304,MATCH($B13,店舗マスタ!$B$5:$B$304,0))) -> 137200 | M13: =IF(OR($B13="",D13=""),"",IF(N(J13)=0,"前年なし",D13/J13)) -> 0.98749271 | N13: =IF(OR($B13="",E13=""),"",IF(N(K13)=0,"前年なし",E13/K13)) -> 0.88475687 | O13: =IF(OR($B13="",F13=""),"",IF(N(L13)=0,"前年なし",F13/L13)) -> 1.7325073
A14: =IF($B14="","","アルチビオ") -> アルチビオ | B14: =IFERROR(INDEX(店舗マスタ!$B$5:$B$304,MATCH("アルチビオ|9",店舗マスタ!$L$5:$L$304,0)),"") -> 32674400 | C14: =IF($B14="","",INDEX(店舗マスタ!$C$5:$C$304,MATCH($B14,店舗マスタ!$B$5:$B$304,0))) -> 伊勢丹浦和店 | D14: =IF($B14="","",INDEX(店舗マスタ!$G$5:$G$304,MATCH($B14,店舗マスタ!$B$5:$B$304,0))) -> 469470 | E14: =IF($B14="","",INDEX(店舗マスタ!$P$5:$P$304,MATCH($B14,店舗マスタ!$B$5:$B$304,0))) -> 206800 | F14: =IF($B14="","",INDEX(店舗マスタ!$R$5:$R$304,MATCH($B14,店舗マスタ!$B$5:$B$304,0))) -> 262670 | G14: =IF(OR($B14="",F14=""),"",IF(D14=0,"-",F14/D14)) -> 0.55950327 | H14: =IF($B14="","",INDEX(店舗マスタ!$H$5:$H$304,MATCH($B14,店舗マスタ!$B$5:$B$304,0))) -> 1100000 | I14: =IF($B14="","",IF(H14=0,"-",D14/H14)) -> 0.42679091 | J14: =IF($B14="","",INDEX(店舗マスタ!$I$5:$I$304,MATCH($B14,店舗マスタ!$B$5:$B$304,0))) -> 1083300 | K14: =IF($B14="","",INDEX(店舗マスタ!$Q$5:$Q$304,MATCH($B14,店舗マスタ!$B$5:$B$304,0))) -> 923300 | L14: =IF($B14="","",INDEX(店舗マスタ!$S$5:$S$304,MATCH($B14,店舗マスタ!$B$5:$B$304,0))) -> 160000 | M14: =IF(OR($B14="",D14=""),"",IF(N(J14)=0,"前年なし",D14/J14)) -> 0.43337026 | N14: =IF(OR($B14="",E14=""),"",IF(N(K14)=0,"前年なし",E14/K14)) -> 0.22397921 | O14: =IF(OR($B14="",F14=""),"",IF(N(L14)=0,"前年なし",F14/L14)) -> 1.6416875
A15: =IF($B15="","","アルチビオ") -> アルチビオ | B15: =IFERROR(INDEX(店舗マスタ!$B$5:$B$304,MATCH("アルチビオ|10",店舗マスタ!$L$5:$L$304,0)),"") -> 32674900 | C15: =IF($B15="","",INDEX(店舗マスタ!$C$5:$C$304,MATCH($B15,店舗マスタ!$B$5:$B$304,0))) -> 松屋銀座本店 | D15: =IF($B15="","",INDEX(店舗マスタ!$G$5:$G$304,MATCH($B15,店舗マスタ!$B$5:$B$304,0))) -> 1425313 | E15: =IF($B15="","",INDEX(店舗マスタ!$P$5:$P$304,MATCH($B15,店舗マスタ!$B$5:$B$304,0))) -> 1207333 | F15: =IF($B15="","",INDEX(店舗マスタ!$R$5:$R$304,MATCH($B15,店舗マスタ!$B$5:$B$304,0))) -> 217980 | G15: =IF(OR($B15="",F15=""),"",IF(D15=0,"-",F15/D15)) -> 0.15293483 | H15: =IF($B15="","",INDEX(店舗マスタ!$H$5:$H$304,MATCH($B15,店舗マスタ!$B$5:$B$304,0))) -> 2512000 | I15: =IF($B15="","",IF(H15=0,"-",D15/H15)) -> 0.56740167 | J15: =IF($B15="","",INDEX(店舗マスタ!$I$5:$I$304,MATCH($B15,店舗マスタ!$B$5:$B$304,0))) -> 1955945 | K15: =IF($B15="","",INDEX(店舗マスタ!$Q$5:$Q$304,MATCH($B15,店舗マスタ!$B$5:$B$304,0))) -> 1911245 | L15: =IF($B15="","",INDEX(店舗マスタ!$S$5:$S$304,MATCH($B15,店舗マスタ!$B$5:$B$304,0))) -> 44700 | M15: =IF(OR($B15="",D15=""),"",IF(N(J15)=0,"前年なし",D15/J15)) -> 0.72870812 | N15: =IF(OR($B15="",E15=""),"",IF(N(K15)=0,"前年なし",E15/K15)) -> 0.63169976 | O15: =IF(OR($B15="",F15=""),"",IF(N(L15)=0,"前年なし",F15/L15)) -> 4.8765101
A16: =IF($B16="","","アルチビオ") -> アルチビオ | B16: =IFERROR(INDEX(店舗マスタ!$B$5:$B$304,MATCH("アルチビオ|11",店舗マスタ!$L$5:$L$304,0)),"") -> 32680600 | C16: =IF($B16="","",INDEX(店舗マスタ!$C$5:$C$304,MATCH($B16,店舗マスタ!$B$5:$B$304,0))) -> 那須ガーデンアウトレット店 | D16: =IF($B16="","",INDEX(店舗マスタ!$G$5:$G$304,MATCH($B16,店舗マスタ!$B$5:$B$304,0))) -> 1066595 | E16: =IF($B16="","",INDEX(店舗マスタ!$P$5:$P$304,MATCH($B16,店舗マスタ!$B$5:$B$304,0))) -> -4655 | F16: =IF($B16="","",INDEX(店舗マスタ!$R$5:$R$304,MATCH($B16,店舗マスタ!$B$5:$B$304,0))) -> 1071250 | G16: =IF(OR($B16="",F16=""),"",IF(D16=0,"-",F16/D16)) -> 1.0043644 | H16: =IF($B16="","",INDEX(店舗マスタ!$H$5:$H$304,MATCH($B16,店舗マスタ!$B$5:$B$304,0))) -> 2600000 | I16: =IF($B16="","",IF(H16=0,"-",D16/H16)) -> 0.41022885 | J16: =IF($B16="","",INDEX(店舗マスタ!$I$5:$I$304,MATCH($B16,店舗マスタ!$B$5:$B$304,0))) -> 1845195 | K16: =IF($B16="","",INDEX(店舗マスタ!$Q$5:$Q$304,MATCH($B16,店舗マスタ!$B$5:$B$304,0))) -> 7355 | L16: =IF($B16="","",INDEX(店舗マスタ!$S$5:$S$304,MATCH($B16,店舗マスタ!$B$5:$B$304,0))) -> 1837840 | M16: =IF(OR($B16="",D16=""),"",IF(N(J16)=0,"前年なし",D16/J16)) -> 0.57803918 | N16: =IF(OR($B16="",E16=""),"",IF(N(K16)=0,"前年なし",E16/K16)) -> -0.63290279 | O16: =IF(OR($B16="",F16=""),"",IF(N(L16)=0,"前年なし",F16/L16)) -> 0.58288534
A17: =IF($B17="","","アルチビオ") | B17: =IFERROR(INDEX(店舗マスタ!$B$5:$B$304,MATCH("アルチビオ|12",店舗マスタ!$L$5:$L$304,0)),"") | C17: =IF($B17="","",INDEX(店舗マスタ!$C$5:$C$304,MATCH($B17,店舗マスタ!$B$5:$B$304,0))) | D17: =IF($B17="","",INDEX(店舗マスタ!$G$5:$G$304,MATCH($B17,店舗マスタ!$B$5:$B$304,0))) | E17: =IF($B17="","",INDEX(店舗マスタ!$P$5:$P$304,MATCH($B17,店舗マスタ!$B$5:$B$304,0))) | F17: =IF($B17="","",INDEX(店舗マスタ!$R$5:$R$304,MATCH($B17,店舗マスタ!$B$5:$B$304,0))) | G17: =IF(OR($B17="",F17=""),"",IF(D17=0,"-",F17/D17)) | H17: =IF($B17="","",INDEX(店舗マスタ!$H$5:$H$304,MATCH($B17,店舗マスタ!$B$5:$B$304,0))) | I17: =IF($B17="","",IF(H17=0,"-",D17/H17)) | J17: =IF($B17="","",INDEX(店舗マスタ!$I$5:$I$304,MATCH($B17,店舗マスタ!$B$5:$B$304,0))) | K17: =IF($B17="","",INDEX(店舗マスタ!$Q$5:$Q$304,MATCH($B17,店舗マスタ!$B$5:$B$304,0))) | L17: =IF($B17="","",INDEX(店舗マスタ!$S$5:$S$304,MATCH($B17,店舗マスタ!$B$5:$B$304,0))) | M17: =IF(OR($B17="",D17=""),"",IF(N(J17)=0,"前年なし",D17/J17)) | N17: =IF(OR($B17="",E17=""),"",IF(N(K17)=0,"前年なし",E17/K17)) | O17: =IF(OR($B17="",F17=""),"",IF(N(L17)=0,"前年なし",F17/L17))
A18: =IF($B18="","","アルチビオ") | B18: =IFERROR(INDEX(店舗マスタ!$B$5:$B$304,MATCH("アルチビオ|13",店舗マスタ!$L$5:$L$304,0)),"") | C18: =IF($B18="","",INDEX(店舗マスタ!$C$5:$C$304,MATCH($B18,店舗マスタ!$B$5:$B$304,0))) | D18: =IF($B18="","",INDEX(店舗マスタ!$G$5:$G$304,MATCH($B18,店舗マスタ!$B$5:$B$304,0))) | E18: =IF($B18="","",INDEX(店舗マスタ!$P$5:$P$304,MATCH($B18,店舗マスタ!$B$5:$B$304,0))) | F18: =IF($B18="","",INDEX(店舗マスタ!$R$5:$R$304,MATCH($B18,店舗マスタ!$B$5:$B$304,0))) | G18: =IF(OR($B18="",F18=""),"",IF(D18=0,"-",F18/D18)) | H18: =IF($B18="","",INDEX(店舗マスタ!$H$5:$H$304,MATCH($B18,店舗マスタ!$B$5:$B$304,0))) | I18: =IF($B18="","",IF(H18=0,"-",D18/H18)) | J18: =IF($B18="","",INDEX(店舗マスタ!$I$5:$I$304,MATCH($B18,店舗マスタ!$B$5:$B$304,0))) | K18: =IF($B18="","",INDEX(店舗マスタ!$Q$5:$Q$304,MATCH($B18,店舗マスタ!$B$5:$B$304,0))) | L18: =IF($B18="","",INDEX(店舗マスタ!$S$5:$S$304,MATCH($B18,店舗マスタ!$B$5:$B$304,0))) | M18: =IF(OR($B18="",D18=""),"",IF(N(J18)=0,"前年なし",D18/J18)) | N18: =IF(OR($B18="",E18=""),"",IF(N(K18)=0,"前年なし",E18/K18)) | O18: =IF(OR($B18="",F18=""),"",IF(N(L18)=0,"前年なし",F18/L18))
A19: =IF($B19="","","アルチビオ") | B19: =IFERROR(INDEX(店舗マスタ!$B$5:$B$304,MATCH("アルチビオ|14",店舗マスタ!$L$5:$L$304,0)),"") | C19: =IF($B19="","",INDEX(店舗マスタ!$C$5:$C$304,MATCH($B19,店舗マスタ!$B$5:$B$304,0))) | D19: =IF($B19="","",INDEX(店舗マスタ!$G$5:$G$304,MATCH($B19,店舗マスタ!$B$5:$B$304,0))) | E19: =IF($B19="","",INDEX(店舗マスタ!$P$5:$P$304,MATCH($B19,店舗マスタ!$B$5:$B$304,0))) | F19: =IF($B19="","",INDEX(店舗マスタ!$R$5:$R$304,MATCH($B19,店舗マスタ!$B$5:$B$304,0))) | G19: =IF(OR($B19="",F19=""),"",IF(D19=0,"-",F19/D19)) | H19: =IF($B19="","",INDEX(店舗マスタ!$H$5:$H$304,MATCH($B19,店舗マスタ!$B$5:$B$304,0))) | I19: =IF($B19="","",IF(H19=0,"-",D19/H19)) | J19: =IF($B19="","",INDEX(店舗マスタ!$I$5:$I$304,MATCH($B19,店舗マスタ!$B$5:$B$304,0))) | K19: =IF($B19="","",INDEX(店舗マスタ!$Q$5:$Q$304,MATCH($B19,店舗マスタ!$B$5:$B$304,0))) | L19: =IF($B19="","",INDEX(店舗マスタ!$S$5:$S$304,MATCH($B19,店舗マスタ!$B$5:$B$304,0))) | M19: =IF(OR($B19="",D19=""),"",IF(N(J19)=0,"前年なし",D19/J19)) | N19: =IF(OR($B19="",E19=""),"",IF(N(K19)=0,"前年なし",E19/K19)) | O19: =IF(OR($B19="",F19=""),"",IF(N(L19)=0,"前年なし",F19/L19))
A20: ="アルチビオ 小計（"&COUNT(D6:D19)&"店舗）" -> アルチビオ 小計（11店舗） | D20: =SUBTOTAL(9,D6:D19) -> 21514701 | E20: =SUBTOTAL(9,E6:E19) -> 16221041 | F20: =SUBTOTAL(9,F6:F19) -> 5293660 | G20: =IF(D20=0,"-",F20/D20) -> 0.2460485 | H20: =SUBTOTAL(9,H6:H19) -> 26854000 | I20: =IF(H20=0,"-",D20/H20) -> 0.80117305 | J20: =SUBTOTAL(9,J6:J19) -> 24125211 | K20: =SUBTOTAL(9,K6:K19) -> 18543471 | L20: =SUBTOTAL(9,L6:L19) -> 5581740 | M20: =IF(J20=0,"-",D20/J20) -> 0.89179328 | N20: =IF(K20=0,"-",E20/K20) -> 0.87475754 | O20: =IF(L20=0,"-",F20/L20) -> 0.94838885
A21: =IF($B21="","","スタジオピッコーネ／ピッコーネクラブ") -> スタジオピッコーネ／ピッコーネクラブ | B21: =IFERROR(INDEX(店舗マスタ!$B$5:$B$304,MATCH("スタジオピッコーネ／ピッコーネクラブ|1",店舗マスタ!$L$5:$L$304,0)),"") -> 32570200 | C21: =IF($B21="","",INDEX(店舗マスタ!$C$5:$C$304,MATCH($B21,店舗マスタ!$B$5:$B$304,0))) -> 高島屋大阪店 | D21: =IF($B21="","",INDEX(店舗マスタ!$G$5:$G$304,MATCH($B21,店舗マスタ!$B$5:$B$304,0))) -> 3137700 | E21: =IF($B21="","",INDEX(店舗マスタ!$P$5:$P$304,MATCH($B21,店舗マスタ!$B$5:$B$304,0))) -> 3137700 | F21: =IF($B21="","",INDEX(店舗マスタ!$R$5:$R$304,MATCH($B21,店舗マスタ!$B$5:$B$304,0))) -> 0 | G21: =IF(OR($B21="",F21=""),"",IF(D21=0,"-",F21/D21)) -> 0 | H21: =IF($B21="","",INDEX(店舗マスタ!$H$5:$H$304,MATCH($B21,店舗マスタ!$B$5:$B$304,0))) -> 4320000 | I21: =IF($B21="","",IF(H21=0,"-",D21/H21)) -> 0.72631944 | J21: =IF($B21="","",INDEX(店舗マスタ!$I$5:$I$304,MATCH($B21,店舗マスタ!$B$5:$B$304,0))) -> 4174590 | K21: =IF($B21="","",INDEX(店舗マスタ!$Q$5:$Q$304,MATCH($B21,店舗マスタ!$B$5:$B$304,0))) -> 4174590 | L21: =IF($B21="","",INDEX(店舗マスタ!$S$5:$S$304,MATCH($B21,店舗マスタ!$B$5:$B$304,0))) -> 0 | M21: =IF(OR($B21="",D21=""),"",IF(N(J21)=0,"前年なし",D21/J21)) -> 0.75161872 | N21: =IF(OR($B21="",E21=""),"",IF(N(K21)=0,"前年なし",E21/K21)) -> 0.75161872 | O21: =IF(OR($B21="",F21=""),"",IF(N(L21)=0,"前年なし",F21/L21)) -> 前年なし
A22: =IF($B22="","","スタジオピッコーネ／ピッコーネクラブ") -> スタジオピッコーネ／ピッコーネクラブ | B22: =IFERROR(INDEX(店舗マスタ!$B$5:$B$304,MATCH("スタジオピッコーネ／ピッコーネクラブ|2",店舗マスタ!$L$5:$L$304,0)),"") -> 32572600 | C22: =IF($B22="","",INDEX(店舗マスタ!$C$5:$C$304,MATCH($B22,店舗マスタ!$B$5:$B$304,0))) -> 大丸福岡天神店 | D22: =IF($B22="","",INDEX(店舗マスタ!$G$5:$G$304,MATCH($B22,店舗マスタ!$B$5:$B$304,0))) -> 2083600 | E22: =IF($B22="","",INDEX(店舗マスタ!$P$5:$P$304,MATCH($B22,店舗マスタ!$B$5:$B$304,0))) -> 1681900 | F22: =IF($B22="","",INDEX(店舗マスタ!$R$5:$R$304,MATCH($B22,店舗マスタ!$B$5:$B$304,0))) -> 401700 | G22: =IF(OR($B22="",F22=""),"",IF(D22=0,"-",F22/D22)) -> 0.19279132 | H22: =IF($B22="","",INDEX(店舗マスタ!$H$5:$H$304,MATCH($B22,店舗マスタ!$B$5:$B$304,0))) -> 2100000 | I22: =IF($B22="","",IF(H22=0,"-",D22/H22)) -> 0.99219048 | J22: =IF($B22="","",INDEX(店舗マスタ!$I$5:$I$304,MATCH($B22,店舗マスタ!$B$5:$B$304,0))) -> 1633800 | K22: =IF($B22="","",INDEX(店舗マスタ!$Q$5:$Q$304,MATCH($B22,店舗マスタ!$B$5:$B$304,0))) -> 1430500 | L22: =IF($B22="","",INDEX(店舗マスタ!$S$5:$S$304,MATCH($B22,店舗マスタ!$B$5:$B$304,0))) -> 203300 | M22: =IF(OR($B22="",D22=""),"",IF(N(J22)=0,"前年なし",D22/J22)) -> 1.2753091 | N22: =IF(OR($B22="",E22=""),"",IF(N(K22)=0,"前年なし",E22/K22)) -> 1.1757427 | O22: =IF(OR($B22="",F22=""),"",IF(N(L22)=0,"前年なし",F22/L22)) -> 1.9758977
A23: =IF($B23="","","スタジオピッコーネ／ピッコーネクラブ") -> スタジオピッコーネ／ピッコーネクラブ | B23: =IFERROR(INDEX(店舗マスタ!$B$5:$B$304,MATCH("スタジオピッコーネ／ピッコーネクラブ|3",店舗マスタ!$L$5:$L$304,0)),"") -> 32573200 | C23: =IF($B23="","",INDEX(店舗マスタ!$C$5:$C$304,MATCH($B23,店舗マスタ!$B$5:$B$304,0))) -> あべのハルカス近鉄本店 | D23: =IF($B23="","",INDEX(店舗マスタ!$G$5:$G$304,MATCH($B23,店舗マスタ!$B$5:$B$304,0))) -> 3507580 | E23: =IF($B23="","",INDEX(店舗マスタ!$P$5:$P$304,MATCH($B23,店舗マスタ!$B$5:$B$304,0))) -> 3507580 | F23: =IF($B23="","",INDEX(店舗マスタ!$R$5:$R$304,MATCH($B23,店舗マスタ!$B$5:$B$304,0))) -> 0 | G23: =IF(OR($B23="",F23=""),"",IF(D23=0,"-",F23/D23)) -> 0 | H23: =IF($B23="","",INDEX(店舗マスタ!$H$5:$H$304,MATCH($B23,店舗マスタ!$B$5:$B$304,0))) -> 4120000 | I23: =IF($B23="","",IF(H23=0,"-",D23/H23)) -> 0.85135437 | J23: =IF($B23="","",INDEX(店舗マスタ!$I$5:$I$304,MATCH($B23,店舗マスタ!$B$5:$B$304,0))) -> 4003095 | K23: =IF($B23="","",INDEX(店舗マスタ!$Q$5:$Q$304,MATCH($B23,店舗マスタ!$B$5:$B$304,0))) -> 4003095 | L23: =IF($B23="","",INDEX(店舗マスタ!$S$5:$S$304,MATCH($B23,店舗マスタ!$B$5:$B$304,0))) -> 0 | M23: =IF(OR($B23="",D23=""),"",IF(N(J23)=0,"前年なし",D23/J23)) -> 0.87621703 | N23: =IF(OR($B23="",E23=""),"",IF(N(K23)=0,"前年なし",E23/K23)) -> 0.87621703 | O23: =IF(OR($B23="",F23=""),"",IF(N(L23)=0,"前年なし",F23/L23)) -> 前年なし
A24: =IF($B24="","","スタジオピッコーネ／ピッコーネクラブ") -> スタジオピッコーネ／ピッコーネクラブ | B24: =IFERROR(INDEX(店舗マスタ!$B$5:$B$304,MATCH("スタジオピッコーネ／ピッコーネクラブ|4",店舗マスタ!$L$5:$L$304,0)),"") -> 32573400 | C24: =IF($B24="","",INDEX(店舗マスタ!$C$5:$C$304,MATCH($B24,店舗マスタ!$B$5:$B$304,0))) -> 近鉄百貨店和歌山店 | D24: =IF($B24="","",INDEX(店舗マスタ!$G$5:$G$304,MATCH($B24,店舗マスタ!$B$5:$B$304,0))) -> 1872645 | E24: =IF($B24="","",INDEX(店舗マスタ!$P$5:$P$304,MATCH($B24,店舗マスタ!$B$5:$B$304,0))) -> 1742245 | F24: =IF($B24="","",INDEX(店舗マスタ!$R$5:$R$304,MATCH($B24,店舗マスタ!$B$5:$B$304,0))) -> 130400 | G24: =IF(OR($B24="",F24=""),"",IF(D24=0,"-",F24/D24)) -> 0.069634127 | H24: =IF($B24="","",INDEX(店舗マスタ!$H$5:$H$304,MATCH($B24,店舗マスタ!$B$5:$B$304,0))) -> 2300000 | I24: =IF($B24="","",IF(H24=0,"-",D24/H24)) -> 0.81419348 | J24: =IF($B24="","",INDEX(店舗マスタ!$I$5:$I$304,MATCH($B24,店舗マスタ!$B$5:$B$304,0))) -> 2355195 | K24: =IF($B24="","",INDEX(店舗マスタ!$Q$5:$Q$304,MATCH($B24,店舗マスタ!$B$5:$B$304,0))) -> 2097495 | L24: =IF($B24="","",INDEX(店舗マスタ!$S$5:$S$304,MATCH($B24,店舗マスタ!$B$5:$B$304,0))) -> 257700 | M24: =IF(OR($B24="",D24=""),"",IF(N(J24)=0,"前年なし",D24/J24)) -> 0.79511251 | N24: =IF(OR($B24="",E24=""),"",IF(N(K24)=0,"前年なし",E24/K24)) -> 0.8306313 | O24: =IF(OR($B24="",F24=""),"",IF(N(L24)=0,"前年なし",F24/L24)) -> 0.50601475
A25: =IF($B25="","","スタジオピッコーネ／ピッコーネクラブ") -> スタジオピッコーネ／ピッコーネクラブ | B25: =IFERROR(INDEX(店舗マスタ!$B$5:$B$304,MATCH("スタジオピッコーネ／ピッコーネクラブ|5",店舗マスタ!$L$5:$L$304,0)),"") -> 32573700 | C25: =IF($B25="","",INDEX(店舗マスタ!$C$5:$C$304,MATCH($B25,店舗マスタ!$B$5:$B$304,0))) -> 近鉄百貨店上本町店 | D25: =IF($B25="","",INDEX(店舗マスタ!$G$5:$G$304,MATCH($B25,店舗マスタ!$B$5:$B$304,0))) -> 2637800 | E25: =IF($B25="","",INDEX(店舗マスタ!$P$5:$P$304,MATCH($B25,店舗マスタ!$B$5:$B$304,0))) -> 2566400 | F25: =IF($B25="","",INDEX(店舗マスタ!$R$5:$R$304,MATCH($B25,店舗マスタ!$B$5:$B$304,0))) -> 71400 | G25: =IF(OR($B25="",F25=""),"",IF(D25=0,"-",F25/D25)) -> 0.027068011 | H25: =IF($B25="","",INDEX(店舗マスタ!$H$5:$H$304,MATCH($B25,店舗マスタ!$B$5:$B$304,0))) -> 1950000 | I25: =IF($B25="","",IF(H25=0,"-",D25/H25)) -> 1.3527179 | J25: =IF($B25="","",INDEX(店舗マスタ!$I$5:$I$304,MATCH($B25,店舗マスタ!$B$5:$B$304,0))) -> 1931500 | K25: =IF($B25="","",INDEX(店舗マスタ!$Q$5:$Q$304,MATCH($B25,店舗マスタ!$B$5:$B$304,0))) -> 1559100 | L25: =IF($B25="","",INDEX(店舗マスタ!$S$5:$S$304,MATCH($B25,店舗マスタ!$B$5:$B$304,0))) -> 372400 | M25: =IF(OR($B25="",D25=""),"",IF(N(J25)=0,"前年なし",D25/J25)) -> 1.3656743 | N25: =IF(OR($B25="",E25=""),"",IF(N(K25)=0,"前年なし",E25/K25)) -> 1.6460779 | O25: =IF(OR($B25="",F25=""),"",IF(N(L25)=0,"前年なし",F25/L25)) -> 0.19172932
A26: =IF($B26="","","スタジオピッコーネ／ピッコーネクラブ") -> スタジオピッコーネ／ピッコーネクラブ | B26: =IFERROR(INDEX(店舗マスタ!$B$5:$B$304,MATCH("スタジオピッコーネ／ピッコーネクラブ|6",店舗マスタ!$L$5:$L$304,0)),"") -> 32573800 | C26: =IF($B26="","",INDEX(店舗マスタ!$C$5:$C$304,MATCH($B26,店舗マスタ!$B$5:$B$304,0))) -> 近鉄百貨店奈良店 | D26: =IF($B26="","",INDEX(店舗マスタ!$G$5:$G$304,MATCH($B26,店舗マスタ!$B$5:$B$304,0))) -> 3204200 | E26: =IF($B26="","",INDEX(店舗マスタ!$P$5:$P$304,MATCH($B26,店舗マスタ!$B$5:$B$304,0))) -> 2538670 | F26: =IF($B26="","",INDEX(店舗マスタ!$R$5:$R$304,MATCH($B26,店舗マスタ!$B$5:$B$304,0))) -> 665530 | G26: =IF(OR($B26="",F26=""),"",IF(D26=0,"-",F26/D26)) -> 0.20770551 | H26: =IF($B26="","",INDEX(店舗マスタ!$H$5:$H$304,MATCH($B26,店舗マスタ!$B$5:$B$304,0))) -> 3150000 | I26: =IF($B26="","",IF(H26=0,"-",D26/H26)) -> 1.0172063 | J26: =IF($B26="","",INDEX(店舗マスタ!$I$5:$I$304,MATCH($B26,店舗マスタ!$B$5:$B$304,0))) -> 3186800 | K26: =IF($B26="","",INDEX(店舗マスタ!$Q$5:$Q$304,MATCH($B26,店舗マスタ!$B$5:$B$304,0))) -> 2928400 | L26: =IF($B26="","",INDEX(店舗マスタ!$S$5:$S$304,MATCH($B26,店舗マスタ!$B$5:$B$304,0))) -> 258400 | M26: =IF(OR($B26="",D26=""),"",IF(N(J26)=0,"前年なし",D26/J26)) -> 1.00546 | N26: =IF(OR($B26="",E26=""),"",IF(N(K26)=0,"前年なし",E26/K26)) -> 0.86691367 | O26: =IF(OR($B26="",F26=""),"",IF(N(L26)=0,"前年なし",F26/L26)) -> 2.5755805
A27: =IF($B27="","","スタジオピッコーネ／ピッコーネクラブ") -> スタジオピッコーネ／ピッコーネクラブ | B27: =IFERROR(INDEX(店舗マスタ!$B$5:$B$304,MATCH("スタジオピッコーネ／ピッコーネクラブ|7",店舗マスタ!$L$5:$L$304,0)),"") -> 32573900 | C27: =IF($B27="","",INDEX(店舗マスタ!$C$5:$C$304,MATCH($B27,店舗マスタ!$B$5:$B$304,0))) -> 近鉄百貨店橿原店 | D27: =IF($B27="","",INDEX(店舗マスタ!$G$5:$G$304,MATCH($B27,店舗マスタ!$B$5:$B$304,0))) -> 1744500 | E27: =IF($B27="","",INDEX(店舗マスタ!$P$5:$P$304,MATCH($B27,店舗マスタ!$B$5:$B$304,0))) -> 1039100 | F27: =IF($B27="","",INDEX(店舗マスタ!$R$5:$R$304,MATCH($B27,店舗マスタ!$B$5:$B$304,0))) -> 705400 | G27: =IF(OR($B27="",F27=""),"",IF(D27=0,"-",F27/D27)) -> 0.40435655 | H27: =IF($B27="","",INDEX(店舗マスタ!$H$5:$H$304,MATCH($B27,店舗マスタ!$B$5:$B$304,0))) -> 1880000 | I27: =IF($B27="","",IF(H27=0,"-",D27/H27)) -> 0.92792553 | J27: =IF($B27="","",INDEX(店舗マスタ!$I$5:$I$304,MATCH($B27,店舗マスタ!$B$5:$B$304,0))) -> 1846800 | K27: =IF($B27="","",INDEX(店舗マスタ!$Q$5:$Q$304,MATCH($B27,店舗マスタ!$B$5:$B$304,0))) -> 1430400 | L27: =IF($B27="","",INDEX(店舗マスタ!$S$5:$S$304,MATCH($B27,店舗マスタ!$B$5:$B$304,0))) -> 416400 | M27: =IF(OR($B27="",D27=""),"",IF(N(J27)=0,"前年なし",D27/J27)) -> 0.94460689 | N27: =IF(OR($B27="",E27=""),"",IF(N(K27)=0,"前年なし",E27/K27)) -> 0.72644016 | O27: =IF(OR($B27="",F27=""),"",IF(N(L27)=0,"前年なし",F27/L27)) -> 1.6940442
A28: =IF($B28="","","スタジオピッコーネ／ピッコーネクラブ") -> スタジオピッコーネ／ピッコーネクラブ | B28: =IFERROR(INDEX(店舗マスタ!$B$5:$B$304,MATCH("スタジオピッコーネ／ピッコーネクラブ|8",店舗マスタ!$L$5:$L$304,0)),"") -> 32574100 | C28: =IF($B28="","",INDEX(店舗マスタ!$C$5:$C$304,MATCH($B28,店舗マスタ!$B$5:$B$304,0))) -> 広島三越店 | D28: =IF($B28="","",INDEX(店舗マスタ!$G$5:$G$304,MATCH($B28,店舗マスタ!$B$5:$B$304,0))) -> 1187800 | E28: =IF($B28="","",INDEX(店舗マスタ!$P$5:$P$304,MATCH($B28,店舗マスタ!$B$5:$B$304,0))) -> 819800 | F28: =IF($B28="","",INDEX(店舗マスタ!$R$5:$R$304,MATCH($B28,店舗マスタ!$B$5:$B$304,0))) -> 368000 | G28: =IF(OR($B28="",F28=""),"",IF(D28=0,"-",F28/D28)) -> 0.30981647 | H28: =IF($B28="","",INDEX(店舗マスタ!$H$5:$H$304,MATCH($B28,店舗マスタ!$B$5:$B$304,0))) -> 1700000 | I28: =IF($B28="","",IF(H28=0,"-",D28/H28)) -> 0.69870588 | J28: =IF($B28="","",INDEX(店舗マスタ!$I$5:$I$304,MATCH($B28,店舗マスタ!$B$5:$B$304,0))) -> 1274700 | K28: =IF($B28="","",INDEX(店舗マスタ!$Q$5:$Q$304,MATCH($B28,店舗マスタ!$B$5:$B$304,0))) -> 1158600 | L28: =IF($B28="","",INDEX(店舗マスタ!$S$5:$S$304,MATCH($B28,店舗マスタ!$B$5:$B$304,0))) -> 116100 | M28: =IF(OR($B28="",D28=""),"",IF(N(J28)=0,"前年なし",D28/J28)) -> 0.9318271 | N28: =IF(OR($B28="",E28=""),"",IF(N(K28)=0,"前年なし",E28/K28)) -> 0.70757811 | O28: =IF(OR($B28="",F28=""),"",IF(N(L28)=0,"前年なし",F28/L28)) -> 3.1696813
A29: =IF($B29="","","スタジオピッコーネ／ピッコーネクラブ") -> スタジオピッコーネ／ピッコーネクラブ | B29: =IFERROR(INDEX(店舗マスタ!$B$5:$B$304,MATCH("スタジオピッコーネ／ピッコーネクラブ|9",店舗マスタ!$L$5:$L$304,0)),"") -> 32575700 | C29: =IF($B29="","",INDEX(店舗マスタ!$C$5:$C$304,MATCH($B29,店舗マスタ!$B$5:$B$304,0))) -> 名古屋三越栄店 | D29: =IF($B29="","",INDEX(店舗マスタ!$G$5:$G$304,MATCH($B29,店舗マスタ!$B$5:$B$304,0))) -> 4266900 | E29: =IF($B29="","",INDEX(店舗マスタ!$P$5:$P$304,MATCH($B29,店舗マスタ!$B$5:$B$304,0))) -> 4185000 | F29: =IF($B29="","",INDEX(店舗マスタ!$R$5:$R$304,MATCH($B29,店舗マスタ!$B$5:$B$304,0))) -> 81900 | G29: =IF(OR($B29="",F29=""),"",IF(D29=0,"-",F29/D29)) -> 0.019194263 | H29: =IF($B29="","",INDEX(店舗マスタ!$H$5:$H$304,MATCH($B29,店舗マスタ!$B$5:$B$304,0))) -> 4200000 | I29: =IF($B29="","",IF(H29=0,"-",D29/H29)) -> 1.0159286 | J29: =IF($B29="","",INDEX(店舗マスタ!$I$5:$I$304,MATCH($B29,店舗マスタ!$B$5:$B$304,0))) -> 4153200 | K29: =IF($B29="","",INDEX(店舗マスタ!$Q$5:$Q$304,MATCH($B29,店舗マスタ!$B$5:$B$304,0))) -> 3953300 | L29: =IF($B29="","",INDEX(店舗マスタ!$S$5:$S$304,MATCH($B29,店舗マスタ!$B$5:$B$304,0))) -> 199900 | M29: =IF(OR($B29="",D29=""),"",IF(N(J29)=0,"前年なし",D29/J29)) -> 1.0273765 | N29: =IF(OR($B29="",E29=""),"",IF(N(K29)=0,"前年なし",E29/K29)) -> 1.0586093 | O29: =IF(OR($B29="",F29=""),"",IF(N(L29)=0,"前年なし",F29/L29)) -> 0.40970485
A30: =IF($B30="","","スタジオピッコーネ／ピッコーネクラブ") -> スタジオピッコーネ／ピッコーネクラブ | B30: =IFERROR(INDEX(店舗マスタ!$B$5:$B$304,MATCH("スタジオピッコーネ／ピッコーネクラブ|10",店舗マスタ!$L$5:$L$304,0)),"") -> 32670200 | C30: =IF($B30="","",INDEX(店舗マスタ!$C$5:$C$304,MATCH($B30,店舗マスタ!$B$5:$B$304,0))) -> 高島屋横浜店 | D30: =IF($B30="","",INDEX(店舗マスタ!$G$5:$G$304,MATCH($B30,店舗マスタ!$B$5:$B$304,0))) -> 3134900 | E30: =IF($B30="","",INDEX(店舗マスタ!$P$5:$P$304,MATCH($B30,店舗マスタ!$B$5:$B$304,0))) -> 3118100 | F30: =IF($B30="","",INDEX(店舗マスタ!$R$5:$R$304,MATCH($B30,店舗マスタ!$B$5:$B$304,0))) -> 16800 | G30: =IF(OR($B30="",F30=""),"",IF(D30=0,"-",F30/D30)) -> 0.0053590226 | H30: =IF($B30="","",INDEX(店舗マスタ!$H$5:$H$304,MATCH($B30,店舗マスタ!$B$5:$B$304,0))) -> 6100000 | I30: =IF($B30="","",IF(H30=0,"-",D30/H30)) -> 0.51391803 | J30: =IF($B30="","",INDEX(店舗マスタ!$I$5:$I$304,MATCH($B30,店舗マスタ!$B$5:$B$304,0))) -> 3604510 | K30: =IF($B30="","",INDEX(店舗マスタ!$Q$5:$Q$304,MATCH($B30,店舗マスタ!$B$5:$B$304,0))) -> 3560410 | L30: =IF($B30="","",INDEX(店舗マスタ!$S$5:$S$304,MATCH($B30,店舗マスタ!$B$5:$B$304,0))) -> 44100 | M30: =IF(OR($B30="",D30=""),"",IF(N(J30)=0,"前年なし",D30/J30)) -> 0.86971599 | N30: =IF(OR($B30="",E30=""),"",IF(N(K30)=0,"前年なし",E30/K30)) -> 0.87576993 | O30: =IF(OR($B30="",F30=""),"",IF(N(L30)=0,"前年なし",F30/L30)) -> 0.38095238
A31: =IF($B31="","","スタジオピッコーネ／ピッコーネクラブ") -> スタジオピッコーネ／ピッコーネクラブ | B31: =IFERROR(INDEX(店舗マスタ!$B$5:$B$304,MATCH("スタジオピッコーネ／ピッコーネクラブ|11",店舗マスタ!$L$5:$L$304,0)),"") -> 32670400 | C31: =IF($B31="","",INDEX(店舗マスタ!$C$5:$C$304,MATCH($B31,店舗マスタ!$B$5:$B$304,0))) -> 高島屋高崎店 | D31: =IF($B31="","",INDEX(店舗マスタ!$G$5:$G$304,MATCH($B31,店舗マスタ!$B$5:$B$304,0))) -> 2640520 | E31: =IF($B31="","",INDEX(店舗マスタ!$P$5:$P$304,MATCH($B31,店舗マスタ!$B$5:$B$304,0))) -> 2495520 | F31: =IF($B31="","",INDEX(店舗マスタ!$R$5:$R$304,MATCH($B31,店舗マスタ!$B$5:$B$304,0))) -> 145000 | G31: =IF(OR($B31="",F31=""),"",IF(D31=0,"-",F31/D31)) -> 0.054913426 | H31: =IF($B31="","",INDEX(店舗マスタ!$H$5:$H$304,MATCH($B31,店舗マスタ!$B$5:$B$304,0))) -> 4410000 | I31: =IF($B31="","",IF(H31=0,"-",D31/H31)) -> 0.59875737 | J31: =IF($B31="","",INDEX(店舗マスタ!$I$5:$I$304,MATCH($B31,店舗マスタ!$B$5:$B$304,0))) -> 2984120 | K31: =IF($B31="","",INDEX(店舗マスタ!$Q$5:$Q$304,MATCH($B31,店舗マスタ!$B$5:$B$304,0))) -> 2858120 | L31: =IF($B31="","",INDEX(店舗マスタ!$S$5:$S$304,MATCH($B31,店舗マスタ!$B$5:$B$304,0))) -> 126000 | M31: =IF(OR($B31="",D31=""),"",IF(N(J31)=0,"前年なし",D31/J31)) -> 0.88485718 | N31: =IF(OR($B31="",E31=""),"",IF(N(K31)=0,"前年なし",E31/K31)) -> 0.87313339 | O31: =IF(OR($B31="",F31=""),"",IF(N(L31)=0,"前年なし",F31/L31)) -> 1.1507937
A32: =IF($B32="","","スタジオピッコーネ／ピッコーネクラブ") -> スタジオピッコーネ／ピッコーネクラブ | B32: =IFERROR(INDEX(店舗マスタ!$B$5:$B$304,MATCH("スタジオピッコーネ／ピッコーネクラブ|12",店舗マスタ!$L$5:$L$304,0)),"") -> 32670900 | C32: =IF($B32="","",INDEX(店舗マスタ!$C$5:$C$304,MATCH($B32,店舗マスタ!$B$5:$B$304,0))) -> 東武百貨店池袋店 | D32: =IF($B32="","",INDEX(店舗マスタ!$G$5:$G$304,MATCH($B32,店舗マスタ!$B$5:$B$304,0))) -> 5052300 | E32: =IF($B32="","",INDEX(店舗マスタ!$P$5:$P$304,MATCH($B32,店舗マスタ!$B$5:$B$304,0))) -> 5052300 | F32: =IF($B32="","",INDEX(店舗マスタ!$R$5:$R$304,MATCH($B32,店舗マスタ!$B$5:$B$304,0))) -> 0 | G32: =IF(OR($B32="",F32=""),"",IF(D32=0,"-",F32/D32)) -> 0 | H32: =IF($B32="","",INDEX(店舗マスタ!$H$5:$H$304,MATCH($B32,店舗マスタ!$B$5:$B$304,0))) -> 5370000 | I32: =IF($B32="","",IF(H32=0,"-",D32/H32)) -> 0.94083799 | J32: =IF($B32="","",INDEX(店舗マスタ!$I$5:$I$304,MATCH($B32,店舗マスタ!$B$5:$B$304,0))) -> 5057100 | K32: =IF($B32="","",INDEX(店舗マスタ!$Q$5:$Q$304,MATCH($B32,店舗マスタ!$B$5:$B$304,0))) -> 4861700 | L32: =IF($B32="","",INDEX(店舗マスタ!$S$5:$S$304,MATCH($B32,店舗マスタ!$B$5:$B$304,0))) -> 195400 | M32: =IF(OR($B32="",D32=""),"",IF(N(J32)=0,"前年なし",D32/J32)) -> 0.99905084 | N32: =IF(OR($B32="",E32=""),"",IF(N(K32)=0,"前年なし",E32/K32)) -> 1.0392044 | O32: =IF(OR($B32="",F32=""),"",IF(N(L32)=0,"前年なし",F32/L32)) -> 0
A33: =IF($B33="","","スタジオピッコーネ／ピッコーネクラブ") -> スタジオピッコーネ／ピッコーネクラブ | B33: =IFERROR(INDEX(店舗マスタ!$B$5:$B$304,MATCH("スタジオピッコーネ／ピッコーネクラブ|13",店舗マスタ!$L$5:$L$304,0)),"") -> 32671400 | C33: =IF($B33="","",INDEX(店舗マスタ!$C$5:$C$304,MATCH($B33,店舗マスタ!$B$5:$B$304,0))) -> 日本橋三越本店 | D33: =IF($B33="","",INDEX(店舗マスタ!$G$5:$G$304,MATCH($B33,店舗マスタ!$B$5:$B$304,0))) -> 4633300 | E33: =IF($B33="","",INDEX(店舗マスタ!$P$5:$P$304,MATCH($B33,店舗マスタ!$B$5:$B$304,0))) -> 4361200 | F33: =IF($B33="","",INDEX(店舗マスタ!$R$5:$R$304,MATCH($B33,店舗マスタ!$B$5:$B$304,0))) -> 272100 | G33: =IF(OR($B33="",F33=""),"",IF(D33=0,"-",F33/D33)) -> 0.058727041 | H33: =IF($B33="","",INDEX(店舗マスタ!$H$5:$H$304,MATCH($B33,店舗マスタ!$B$5:$B$304,0))) -> 7990000 | I33: =IF($B33="","",IF(H33=0,"-",D33/H33)) -> 0.57988736 | J33: =IF($B33="","",INDEX(店舗マスタ!$I$5:$I$304,MATCH($B33,店舗マスタ!$B$5:$B$304,0))) -> 5799600 | K33: =IF($B33="","",INDEX(店舗マスタ!$Q$5:$Q$304,MATCH($B33,店舗マスタ!$B$5:$B$304,0))) -> 5799600 | L33: =IF($B33="","",INDEX(店舗マスタ!$S$5:$S$304,MATCH($B33,店舗マスタ!$B$5:$B$304,0))) -> 0 | M33: =IF(OR($B33="",D33=""),"",IF(N(J33)=0,"前年なし",D33/J33)) -> 0.79889992 | N33: =IF(OR($B33="",E33=""),"",IF(N(K33)=0,"前年なし",E33/K33)) -> 0.7519829 | O33: =IF(OR($B33="",F33=""),"",IF(N(L33)=0,"前年なし",F33/L33)) -> 前年なし
A34: =IF($B34="","","スタジオピッコーネ／ピッコーネクラブ") -> スタジオピッコーネ／ピッコーネクラブ | B34: =IFERROR(INDEX(店舗マスタ!$B$5:$B$304,MATCH("スタジオピッコーネ／ピッコーネクラブ|14",店舗マスタ!$L$5:$L$304,0)),"") -> 32671900 | C34: =IF($B34="","",INDEX(店舗マスタ!$C$5:$C$304,MATCH($B34,店舗マスタ!$B$5:$B$304,0))) -> 松坂屋上野店 | D34: =IF($B34="","",INDEX(店舗マスタ!$G$5:$G$304,MATCH($B34,店舗マスタ!$B$5:$B$304,0))) -> 1841920 | E34: =IF($B34="","",INDEX(店舗マスタ!$P$5:$P$304,MATCH($B34,店舗マスタ!$B$5:$B$304,0))) -> 1797020 | F34: =IF($B34="","",INDEX(店舗マスタ!$R$5:$R$304,MATCH($B34,店舗マスタ!$B$5:$B$304,0))) -> 44900 | G34: =IF(OR($B34="",F34=""),"",IF(D34=0,"-",F34/D34)) -> 0.024376737 | H34: =IF($B34="","",INDEX(店舗マスタ!$H$5:$H$304,MATCH($B34,店舗マスタ!$B$5:$B$304,0))) -> 2050000 | I34: =IF($B34="","",IF(H34=0,"-",D34/H34)) -> 0.89849756 | J34: =IF($B34="","",INDEX(店舗マスタ!$I$5:$I$304,MATCH($B34,店舗マスタ!$B$5:$B$304,0))) -> 1940260 | K34: =IF($B34="","",INDEX(店舗マスタ!$Q$5:$Q$304,MATCH($B34,店舗マスタ!$B$5:$B$304,0))) -> 1826860 | L34: =IF($B34="","",INDEX(店舗マスタ!$S$5:$S$304,MATCH($B34,店舗マスタ!$B$5:$B$304,0))) -> 113400 | M34: =IF(OR($B34="",D34=""),"",IF(N(J34)=0,"前年なし",D34/J34)) -> 0.94931607 | N34: =IF(OR($B34="",E34=""),"",IF(N(K34)=0,"前年なし",E34/K34)) -> 0.98366596 | O34: =IF(OR($B34="",F34=""),"",IF(N(L34)=0,"前年なし",F34/L34)) -> 0.39594356
A35: =IF($B35="","","スタジオピッコーネ／ピッコーネクラブ") -> スタジオピッコーネ／ピッコーネクラブ | B35: =IFERROR(INDEX(店舗マスタ!$B$5:$B$304,MATCH("スタジオピッコーネ／ピッコーネクラブ|15",店舗マスタ!$L$5:$L$304,0)),"") -> 32673300 | C35: =IF($B35="","",INDEX(店舗マスタ!$C$5:$C$304,MATCH($B35,店舗マスタ!$B$5:$B$304,0))) -> 松屋銀座本店 | D35: =IF($B35="","",INDEX(店舗マスタ!$G$5:$G$304,MATCH($B35,店舗マスタ!$B$5:$B$304,0))) -> 3005230 | E35: =IF($B35="","",INDEX(店舗マスタ!$P$5:$P$304,MATCH($B35,店舗マスタ!$B$5:$B$304,0))) -> 2938030 | F35: =IF($B35="","",INDEX(店舗マスタ!$R$5:$R$304,MATCH($B35,店舗マスタ!$B$5:$B$304,0))) -> 67200 | G35: =IF(OR($B35="",F35=""),"",IF(D35=0,"-",F35/D35)) -> 0.022361017 | H35: =IF($B35="","",INDEX(店舗マスタ!$H$5:$H$304,MATCH($B35,店舗マスタ!$B$5:$B$304,0))) -> 3050000 | I35: =IF($B35="","",IF(H35=0,"-",D35/H35)) -> 0.98532131 | J35: =IF($B35="","",INDEX(店舗マスタ!$I$5:$I$304,MATCH($B35,店舗マスタ!$B$5:$B$304,0))) -> 2843445 | K35: =IF($B35="","",INDEX(店舗マスタ!$Q$5:$Q$304,MATCH($B35,店舗マスタ!$B$5:$B$304,0))) -> 2786545 | L35: =IF($B35="","",INDEX(店舗マスタ!$S$5:$S$304,MATCH($B35,店舗マスタ!$B$5:$B$304,0))) -> 56900 | M35: =IF(OR($B35="",D35=""),"",IF(N(J35)=0,"前年なし",D35/J35)) -> 1.0568975 | N35: =IF(OR($B35="",E35=""),"",IF(N(K35)=0,"前年なし",E35/K35)) -> 1.054363 | O35: =IF(OR($B35="",F35=""),"",IF(N(L35)=0,"前年なし",F35/L35)) -> 1.1810193
A36: =IF($B36="","","スタジオピッコーネ／ピッコーネクラブ") -> スタジオピッコーネ／ピッコーネクラブ | B36: =IFERROR(INDEX(店舗マスタ!$B$5:$B$304,MATCH("スタジオピッコーネ／ピッコーネクラブ|16",店舗マスタ!$L$5:$L$304,0)),"") -> 32674100 | C36: =IF($B36="","",INDEX(店舗マスタ!$C$5:$C$304,MATCH($B36,店舗マスタ!$B$5:$B$304,0))) -> 東武百貨店船橋店 | D36: =IF($B36="","",INDEX(店舗マスタ!$G$5:$G$304,MATCH($B36,店舗マスタ!$B$5:$B$304,0))) -> 2155045 | E36: =IF($B36="","",INDEX(店舗マスタ!$P$5:$P$304,MATCH($B36,店舗マスタ!$B$5:$B$304,0))) -> 2039545 | F36: =IF($B36="","",INDEX(店舗マスタ!$R$5:$R$304,MATCH($B36,店舗マスタ!$B$5:$B$304,0))) -> 115500 | G36: =IF(OR($B36="",F36=""),"",IF(D36=0,"-",F36/D36)) -> 0.053595169 | H36: =IF($B36="","",INDEX(店舗マスタ!$H$5:$H$304,MATCH($B36,店舗マスタ!$B$5:$B$304,0))) -> 1923000 | I36: =IF($B36="","",IF(H36=0,"-",D36/H36)) -> 1.1206682 | J36: =IF($B36="","",INDEX(店舗マスタ!$I$5:$I$304,MATCH($B36,店舗マスタ!$B$5:$B$304,0))) -> 1662095 | K36: =IF($B36="","",INDEX(店舗マスタ!$Q$5:$Q$304,MATCH($B36,店舗マスタ!$B$5:$B$304,0))) -> 1484495 | L36: =IF($B36="","",INDEX(店舗マスタ!$S$5:$S$304,MATCH($B36,店舗マスタ!$B$5:$B$304,0))) -> 177600 | M36: =IF(OR($B36="",D36=""),"",IF(N(J36)=0,"前年なし",D36/J36)) -> 1.2965835 | N36: =IF(OR($B36="",E36=""),"",IF(N(K36)=0,"前年なし",E36/K36)) -> 1.3738982 | O36: =IF(OR($B36="",F36=""),"",IF(N(L36)=0,"前年なし",F36/L36)) -> 0.65033784
A37: =IF($B37="","","スタジオピッコーネ／ピッコーネクラブ") -> スタジオピッコーネ／ピッコーネクラブ | B37: =IFERROR(INDEX(店舗マスタ!$B$5:$B$304,MATCH("スタジオピッコーネ／ピッコーネクラブ|17",店舗マスタ!$L$5:$L$304,0)),"") -> 32674500 | C37: =IF($B37="","",INDEX(店舗マスタ!$C$5:$C$304,MATCH($B37,店舗マスタ!$B$5:$B$304,0))) -> 仙台三越 | D37: =IF($B37="","",INDEX(店舗マスタ!$G$5:$G$304,MATCH($B37,店舗マスタ!$B$5:$B$304,0))) -> 1266300 | E37: =IF($B37="","",INDEX(店舗マスタ!$P$5:$P$304,MATCH($B37,店舗マスタ!$B$5:$B$304,0))) -> 1266300 | F37: =IF($B37="","",INDEX(店舗マスタ!$R$5:$R$304,MATCH($B37,店舗マスタ!$B$5:$B$304,0))) -> 0 | G37: =IF(OR($B37="",F37=""),"",IF(D37=0,"-",F37/D37)) -> 0 | H37: =IF($B37="","",INDEX(店舗マスタ!$H$5:$H$304,MATCH($B37,店舗マスタ!$B$5:$B$304,0))) -> 1250000 | I37: =IF($B37="","",IF(H37=0,"-",D37/H37)) -> 1.01304 | J37: =IF($B37="","",INDEX(店舗マスタ!$I$5:$I$304,MATCH($B37,店舗マスタ!$B$5:$B$304,0))) -> 948000 | K37: =IF($B37="","",INDEX(店舗マスタ!$Q$5:$Q$304,MATCH($B37,店舗マスタ!$B$5:$B$304,0))) -> 921000 | L37: =IF($B37="","",INDEX(店舗マスタ!$S$5:$S$304,MATCH($B37,店舗マスタ!$B$5:$B$304,0))) -> 27000 | M37: =IF(OR($B37="",D37=""),"",IF(N(J37)=0,"前年なし",D37/J37)) -> 1.3357595 | N37: =IF(OR($B37="",E37=""),"",IF(N(K37)=0,"前年なし",E37/K37)) -> 1.3749186 | O37: =IF(OR($B37="",F37=""),"",IF(N(L37)=0,"前年なし",F37/L37)) -> 0
A38: =IF($B38="","","スタジオピッコーネ／ピッコーネクラブ") -> スタジオピッコーネ／ピッコーネクラブ | B38: =IFERROR(INDEX(店舗マスタ!$B$5:$B$304,MATCH("スタジオピッコーネ／ピッコーネクラブ|18",店舗マスタ!$L$5:$L$304,0)),"") -> 32675600 | C38: =IF($B38="","",INDEX(店舗マスタ!$C$5:$C$304,MATCH($B38,店舗マスタ!$B$5:$B$304,0))) -> ながの東急百貨店 | D38: =IF($B38="","",INDEX(店舗マスタ!$G$5:$G$304,MATCH($B38,店舗マスタ!$B$5:$B$304,0))) -> 2648700 | E38: =IF($B38="","",INDEX(店舗マスタ!$P$5:$P$304,MATCH($B38,店舗マスタ!$B$5:$B$304,0))) -> 2585700 | F38: =IF($B38="","",INDEX(店舗マスタ!$R$5:$R$304,MATCH($B38,店舗マスタ!$B$5:$B$304,0))) -> 63000 | G38: =IF(OR($B38="",F38=""),"",IF(D38=0,"-",F38/D38)) -> 0.023785253 | H38: =IF($B38="","",INDEX(店舗マスタ!$H$5:$H$304,MATCH($B38,店舗マスタ!$B$5:$B$304,0))) -> 3910000 | I38: =IF($B38="","",IF(H38=0,"-",D38/H38)) -> 0.67741688 | J38: =IF($B38="","",INDEX(店舗マスタ!$I$5:$I$304,MATCH($B38,店舗マスタ!$B$5:$B$304,0))) -> 3232800 | K38: =IF($B38="","",INDEX(店舗マスタ!$Q$5:$Q$304,MATCH($B38,店舗マスタ!$B$5:$B$304,0))) -> 3129200 | L38: =IF($B38="","",INDEX(店舗マスタ!$S$5:$S$304,MATCH($B38,店舗マスタ!$B$5:$B$304,0))) -> 103600 | M38: =IF(OR($B38="",D38=""),"",IF(N(J38)=0,"前年なし",D38/J38)) -> 0.81932071 | N38: =IF(OR($B38="",E38=""),"",IF(N(K38)=0,"前年なし",E38/K38)) -> 0.82631343 | O38: =IF(OR($B38="",F38=""),"",IF(N(L38)=0,"前年なし",F38/L38)) -> 0.60810811
A39: =IF($B39="","","スタジオピッコーネ／ピッコーネクラブ") -> スタジオピッコーネ／ピッコーネクラブ | B39: =IFERROR(INDEX(店舗マスタ!$B$5:$B$304,MATCH("スタジオピッコーネ／ピッコーネクラブ|19",店舗マスタ!$L$5:$L$304,0)),"") -> 32675700 | C39: =IF($B39="","",INDEX(店舗マスタ!$C$5:$C$304,MATCH($B39,店舗マスタ!$B$5:$B$304,0))) -> 静岡伊勢丹 | D39: =IF($B39="","",INDEX(店舗マスタ!$G$5:$G$304,MATCH($B39,店舗マスタ!$B$5:$B$304,0))) -> 1267300 | E39: =IF($B39="","",INDEX(店舗マスタ!$P$5:$P$304,MATCH($B39,店舗マスタ!$B$5:$B$304,0))) -> 832100 | F39: =IF($B39="","",INDEX(店舗マスタ!$R$5:$R$304,MATCH($B39,店舗マスタ!$B$5:$B$304,0))) -> 435200 | G39: =IF(OR($B39="",F39=""),"",IF(D39=0,"-",F39/D39)) -> 0.34340724 | H39: =IF($B39="","",INDEX(店舗マスタ!$H$5:$H$304,MATCH($B39,店舗マスタ!$B$5:$B$304,0))) -> 1260000 | I39: =IF($B39="","",IF(H39=0,"-",D39/H39)) -> 1.0057937 | J39: =IF($B39="","",INDEX(店舗マスタ!$I$5:$I$304,MATCH($B39,店舗マスタ!$B$5:$B$304,0))) -> 910300 | K39: =IF($B39="","",INDEX(店舗マスタ!$Q$5:$Q$304,MATCH($B39,店舗マスタ!$B$5:$B$304,0))) -> 724100 | L39: =IF($B39="","",INDEX(店舗マスタ!$S$5:$S$304,MATCH($B39,店舗マスタ!$B$5:$B$304,0))) -> 186200 | M39: =IF(OR($B39="",D39=""),"",IF(N(J39)=0,"前年なし",D39/J39)) -> 1.3921784 | N39: =IF(OR($B39="",E39=""),"",IF(N(K39)=0,"前年なし",E39/K39)) -> 1.1491507 | O39: =IF(OR($B39="",F39=""),"",IF(N(L39)=0,"前年なし",F39/L39)) -> 2.3372718
A40: =IF($B40="","","スタジオピッコーネ／ピッコーネクラブ") -> スタジオピッコーネ／ピッコーネクラブ | B40: =IFERROR(INDEX(店舗マスタ!$B$5:$B$304,MATCH("スタジオピッコーネ／ピッコーネクラブ|20",店舗マスタ!$L$5:$L$304,0)),"") -> 32675800 | C40: =IF($B40="","",INDEX(店舗マスタ!$C$5:$C$304,MATCH($B40,店舗マスタ!$B$5:$B$304,0))) -> 伊勢丹立川店 | D40: =IF($B40="","",INDEX(店舗マスタ!$G$5:$G$304,MATCH($B40,店舗マスタ!$B$5:$B$304,0))) -> 1418275 | E40: =IF($B40="","",INDEX(店舗マスタ!$P$5:$P$304,MATCH($B40,店舗マスタ!$B$5:$B$304,0))) -> 1380275 | F40: =IF($B40="","",INDEX(店舗マスタ!$R$5:$R$304,MATCH($B40,店舗マスタ!$B$5:$B$304,0))) -> 38000 | G40: =IF(OR($B40="",F40=""),"",IF(D40=0,"-",F40/D40)) -> 0.026793111 | H40: =IF($B40="","",INDEX(店舗マスタ!$H$5:$H$304,MATCH($B40,店舗マスタ!$B$5:$B$304,0))) -> 2500000 | I40: =IF($B40="","",IF(H40=0,"-",D40/H40)) -> 0.56731 | J40: =IF($B40="","",INDEX(店舗マスタ!$I$5:$I$304,MATCH($B40,店舗マスタ!$B$5:$B$304,0))) -> 2424400 | K40: =IF($B40="","",INDEX(店舗マスタ!$Q$5:$Q$304,MATCH($B40,店舗マスタ!$B$5:$B$304,0))) -> 2326900 | L40: =IF($B40="","",INDEX(店舗マスタ!$S$5:$S$304,MATCH($B40,店舗マスタ!$B$5:$B$304,0))) -> 97500 | M40: =IF(OR($B40="",D40=""),"",IF(N(J40)=0,"前年なし",D40/J40)) -> 0.58500041 | N40: =IF(OR($B40="",E40=""),"",IF(N(K40)=0,"前年なし",E40/K40)) -> 0.59318192 | O40: =IF(OR($B40="",F40=""),"",IF(N(L40)=0,"前年なし",F40/L40)) -> 0.38974359
A41: =IF($B41="","","スタジオピッコーネ／ピッコーネクラブ") -> スタジオピッコーネ／ピッコーネクラブ | B41: =IFERROR(INDEX(店舗マスタ!$B$5:$B$304,MATCH("スタジオピッコーネ／ピッコーネクラブ|21",店舗マスタ!$L$5:$L$304,0)),"") -> 32676200 | C41: =IF($B41="","",INDEX(店舗マスタ!$C$5:$C$304,MATCH($B41,店舗マスタ!$B$5:$B$304,0))) -> 東武宇都宮百貨店 | D41: =IF($B41="","",INDEX(店舗マスタ!$G$5:$G$304,MATCH($B41,店舗マスタ!$B$5:$B$304,0))) -> 1843700 | E41: =IF($B41="","",INDEX(店舗マスタ!$P$5:$P$304,MATCH($B41,店舗マスタ!$B$5:$B$304,0))) -> 1540400 | F41: =IF($B41="","",INDEX(店舗マスタ!$R$5:$R$304,MATCH($B41,店舗マスタ!$B$5:$B$304,0))) -> 303300 | G41: =IF(OR($B41="",F41=""),"",IF(D41=0,"-",F41/D41)) -> 0.16450616 | H41: =IF($B41="","",INDEX(店舗マスタ!$H$5:$H$304,MATCH($B41,店舗マスタ!$B$5:$B$304,0))) -> 1450000 | I41: =IF($B41="","",IF(H41=0,"-",D41/H41)) -> 1.2715172 | J41: =IF($B41="","",INDEX(店舗マスタ!$I$5:$I$304,MATCH($B41,店舗マスタ!$B$5:$B$304,0))) -> 1179400 | K41: =IF($B41="","",INDEX(店舗マスタ!$Q$5:$Q$304,MATCH($B41,店舗マスタ!$B$5:$B$304,0))) -> 988000 | L41: =IF($B41="","",INDEX(店舗マスタ!$S$5:$S$304,MATCH($B41,店舗マスタ!$B$5:$B$304,0))) -> 191400 | M41: =IF(OR($B41="",D41=""),"",IF(N(J41)=0,"前年なし",D41/J41)) -> 1.5632525 | N41: =IF(OR($B41="",E41=""),"",IF(N(K41)=0,"前年なし",E41/K41)) -> 1.5591093 | O41: =IF(OR($B41="",F41=""),"",IF(N(L41)=0,"前年なし",F41/L41)) -> 1.5846395
...

Sheet 店舗別明細
A1: =取込チェック!$H$3 -> POS売上 予算・前年対比（2026年9月度／前年同月 2025年9月）
A2: 売上はPB合計（プロパー＋バーゲン）。ブランド系統ごとに店舗コード順で自動表示します。
A4: ブランド系統 | B4: 店舗コード | C4: 施設・店舗名 | D4: 取扱ブランド | E4: 売上金額 | F4: 予算金額 | G4: 予算達成率 | H4: 予算差額 | I4: 前年売上金額 | J4: 前年対比 | K4: 前年差額
A5: =IF($B5="","","アルチビオ") -> アルチビオ | B5: =IFERROR(INDEX(店舗マスタ!$B$5:$B$304,MATCH("アルチビオ|1",店舗マスタ!$L$5:$L$304,0)),"") -> 32570100 | C5: =IF($B5="","",INDEX(店舗マスタ!$C$5:$C$304,MATCH($B5,店舗マスタ!$B$5:$B$304,0))) -> 高島屋大阪店 | D5: =IF($B5="","",INDEX(店舗マスタ!$D$5:$D$304,MATCH($B5,店舗マスタ!$B$5:$B$304,0))) -> アルチビオ | E5: =IF($B5="","",INDEX(店舗マスタ!$G$5:$G$304,MATCH($B5,店舗マスタ!$B$5:$B$304,0))) -> 2048565 | F5: =IF($B5="","",INDEX(店舗マスタ!$H$5:$H$304,MATCH($B5,店舗マスタ!$B$5:$B$304,0))) -> 2150000 | G5: =IF($B5="","",IF(F5=0,"-",E5/F5)) -> 0.95282093 | H5: =IF($B5="","",E5-F5) -> -101435 | I5: =IF($B5="","",INDEX(店舗マスタ!$I$5:$I$304,MATCH($B5,店舗マスタ!$B$5:$B$304,0))) -> 2098500 | J5: =IF($B5="","",IF(I5=0,"前年実績なし",E5/I5)) -> 0.97620443 | K5: =IF($B5="","",E5-I5) -> -49935
A6: =IF($B6="","","アルチビオ") -> アルチビオ | B6: =IFERROR(INDEX(店舗マスタ!$B$5:$B$304,MATCH("アルチビオ|2",店舗マスタ!$L$5:$L$304,0)),"") -> 32571600 | C6: =IF($B6="","",INDEX(店舗マスタ!$C$5:$C$304,MATCH($B6,店舗マスタ!$B$5:$B$304,0))) -> ジェイアール名古屋タカシマヤ店 | D6: =IF($B6="","",INDEX(店舗マスタ!$D$5:$D$304,MATCH($B6,店舗マスタ!$B$5:$B$304,0))) -> アルチビオ | E6: =IF($B6="","",INDEX(店舗マスタ!$G$5:$G$304,MATCH($B6,店舗マスタ!$B$5:$B$304,0))) -> 3250690 | F6: =IF($B6="","",INDEX(店舗マスタ!$H$5:$H$304,MATCH($B6,店舗マスタ!$B$5:$B$304,0))) -> 3681000 | G6: =IF($B6="","",IF(F6=0,"-",E6/F6)) -> 0.8830997 | H6: =IF($B6="","",E6-F6) -> -430310 | I6: =IF($B6="","",INDEX(店舗マスタ!$I$5:$I$304,MATCH($B6,店舗マスタ!$B$5:$B$304,0))) -> 3216380 | J6: =IF($B6="","",IF(I6=0,"前年実績なし",E6/I6)) -> 1.0106673 | K6: =IF($B6="","",E6-I6) -> 34310
A7: =IF($B7="","","アルチビオ") -> アルチビオ | B7: =IFERROR(INDEX(店舗マスタ!$B$5:$B$304,MATCH("アルチビオ|3",店舗マスタ!$L$5:$L$304,0)),"") -> 32580400 | C7: =IF($B7="","",INDEX(店舗マスタ!$C$5:$C$304,MATCH($B7,店舗マスタ!$B$5:$B$304,0))) -> ハービスPLAZA店 | D7: =IF($B7="","",INDEX(店舗マスタ!$D$5:$D$304,MATCH($B7,店舗マスタ!$B$5:$B$304,0))) -> アルチビオ | E7: =IF($B7="","",INDEX(店舗マスタ!$G$5:$G$304,MATCH($B7,店舗マスタ!$B$5:$B$304,0))) -> 2922845 | F7: =IF($B7="","",INDEX(店舗マスタ!$H$5:$H$304,MATCH($B7,店舗マスタ!$B$5:$B$304,0))) -> 3613000 | G7: =IF($B7="","",IF(F7=0,"-",E7/F7)) -> 0.80898007 | H7: =IF($B7="","",E7-F7) -> -690155 | I7: =IF($B7="","",INDEX(店舗マスタ!$I$5:$I$304,MATCH($B7,店舗マスタ!$B$5:$B$304,0))) -> 3478940 | J7: =IF($B7="","",IF(I7=0,"前年実績なし",E7/I7)) -> 0.8401539 | K7: =IF($B7="","",E7-I7) -> -556095
A8: =IF($B8="","","アルチビオ") -> アルチビオ | B8: =IFERROR(INDEX(店舗マスタ!$B$5:$B$304,MATCH("アルチビオ|4",店舗マスタ!$L$5:$L$304,0)),"") -> 32581000 | C8: =IF($B8="","",INDEX(店舗マスタ!$C$5:$C$304,MATCH($B8,店舗マスタ!$B$5:$B$304,0))) -> 堀江店 | D8: =IF($B8="","",INDEX(店舗マスタ!$D$5:$D$304,MATCH($B8,店舗マスタ!$B$5:$B$304,0))) -> アルチビオ | E8: =IF($B8="","",INDEX(店舗マスタ!$G$5:$G$304,MATCH($B8,店舗マスタ!$B$5:$B$304,0))) -> 1572240 | F8: =IF($B8="","",INDEX(店舗マスタ!$H$5:$H$304,MATCH($B8,店舗マスタ!$B$5:$B$304,0))) -> 2787000 | G8: =IF($B8="","",IF(F8=0,"-",E8/F8)) -> 0.56413348 | H8: =IF($B8="","",E8-F8) -> -1214760 | I8: =IF($B8="","",INDEX(店舗マスタ!$I$5:$I$304,MATCH($B8,店舗マスタ!$B$5:$B$304,0))) -> 2688196 | J8: =IF($B8="","",IF(I8=0,"前年実績なし",E8/I8)) -> 0.58486807 | K8: =IF($B8="","",E8-I8) -> -1115956
A9: =IF($B9="","","アルチビオ") -> アルチビオ | B9: =IFERROR(INDEX(店舗マスタ!$B$5:$B$304,MATCH("アルチビオ|5",店舗マスタ!$L$5:$L$304,0)),"") -> 32670600 | C9: =IF($B9="","",INDEX(店舗マスタ!$C$5:$C$304,MATCH($B9,店舗マスタ!$B$5:$B$304,0))) -> 高島屋新宿店 | D9: =IF($B9="","",INDEX(店舗マスタ!$D$5:$D$304,MATCH($B9,店舗マスタ!$B$5:$B$304,0))) -> アルチビオ | E9: =IF($B9="","",INDEX(店舗マスタ!$G$5:$G$304,MATCH($B9,店舗マスタ!$B$5:$B$304,0))) -> 2991974 | F9: =IF($B9="","",INDEX(店舗マスタ!$H$5:$H$304,MATCH($B9,店舗マスタ!$B$5:$B$304,0))) -> 2571000 | G9: =IF($B9="","",IF(F9=0,"-",E9/F9)) -> 1.1637394 | H9: =IF($B9="","",E9-F9) -> 420974 | I9: =IF($B9="","",INDEX(店舗マスタ!$I$5:$I$304,MATCH($B9,店舗マスタ!$B$5:$B$304,0))) -> 2496485 | J9: =IF($B9="","",IF(I9=0,"前年実績なし",E9/I9)) -> 1.1984747 | K9: =IF($B9="","",E9-I9) -> 495489
A10: =IF($B10="","","アルチビオ") -> アルチビオ | B10: =IFERROR(INDEX(店舗マスタ!$B$5:$B$304,MATCH("アルチビオ|6",店舗マスタ!$L$5:$L$304,0)),"") -> 32673500 | C10: =IF($B10="","",INDEX(店舗マスタ!$C$5:$C$304,MATCH($B10,店舗マスタ!$B$5:$B$304,0))) -> 日本橋三越本店 | D10: =IF($B10="","",INDEX(店舗マスタ!$D$5:$D$304,MATCH($B10,店舗マスタ!$B$5:$B$304,0))) -> アルチビオ | E10: =IF($B10="","",INDEX(店舗マスタ!$G$5:$G$304,MATCH($B10,店舗マスタ!$B$5:$B$304,0))) -> 3069240 | F10: =IF($B10="","",INDEX(店舗マスタ!$H$5:$H$304,MATCH($B10,店舗マスタ!$B$5:$B$304,0))) -> 2691000 | G10: =IF($B10="","",IF(F10=0,"-",E10/F10)) -> 1.1405574 | H10: =IF($B10="","",E10-F10) -> 378240 | I10: =IF($B10="","",INDEX(店舗マスタ!$I$5:$I$304,MATCH($B10,店舗マスタ!$B$5:$B$304,0))) -> 2647100 | J10: =IF($B10="","",IF(I10=0,"前年実績なし",E10/I10)) -> 1.1594726 | K10: =IF($B10="","",E10-I10) -> 422140
A11: =IF($B11="","","アルチビオ") -> アルチビオ | B11: =IFERROR(INDEX(店舗マスタ!$B$5:$B$304,MATCH("アルチビオ|7",店舗マスタ!$L$5:$L$304,0)),"") -> 32673800 | C11: =IF($B11="","",INDEX(店舗マスタ!$C$5:$C$304,MATCH($B11,店舗マスタ!$B$5:$B$304,0))) -> 高島屋横浜店 | D11: =IF($B11="","",INDEX(店舗マスタ!$D$5:$D$304,MATCH($B11,店舗マスタ!$B$5:$B$304,0))) -> アルチビオ | E11: =IF($B11="","",INDEX(店舗マスタ!$G$5:$G$304,MATCH($B11,店舗マスタ!$B$5:$B$304,0))) -> 1579789 | F11: =IF($B11="","",INDEX(店舗マスタ!$H$5:$H$304,MATCH($B11,店舗マスタ!$B$5:$B$304,0))) -> 1900000 | G11: =IF($B11="","",IF(F11=0,"-",E11/F11)) -> 0.83146789 | H11: =IF($B11="","",E11-F11) -> -320211 | I11: =IF($B11="","",INDEX(店舗マスタ!$I$5:$I$304,MATCH($B11,店舗マスタ!$B$5:$B$304,0))) -> 1483030 | J11: =IF($B11="","",IF(I11=0,"前年実績なし",E11/I11)) -> 1.0652441 | K11: =IF($B11="","",E11-I11) -> 96759
A12: =IF($B12="","","アルチビオ") -> アルチビオ | B12: =IFERROR(INDEX(店舗マスタ!$B$5:$B$304,MATCH("アルチビオ|8",店舗マスタ!$L$5:$L$304,0)),"") -> 32673900 | C12: =IF($B12="","",INDEX(店舗マスタ!$C$5:$C$304,MATCH($B12,店舗マスタ!$B$5:$B$304,0))) -> 高島屋高崎店 | D12: =IF($B12="","",INDEX(店舗マスタ!$D$5:$D$304,MATCH($B12,店舗マスタ!$B$5:$B$304,0))) -> アルチビオ | E12: =IF($B12="","",INDEX(店舗マスタ!$G$5:$G$304,MATCH($B12,店舗マスタ!$B$5:$B$304,0))) -> 1117980 | F12: =IF($B12="","",INDEX(店舗マスタ!$H$5:$H$304,MATCH($B12,店舗マスタ!$B$5:$B$304,0))) -> 1249000 | G12: =IF($B12="","",IF(F12=0,"-",E12/F12)) -> 0.89510008 | H12: =IF($B12="","",E12-F12) -> -131020 | I12: =IF($B12="","",INDEX(店舗マスタ!$I$5:$I$304,MATCH($B12,店舗マスタ!$B$5:$B$304,0))) -> 1132140 | J12: =IF($B12="","",IF(I12=0,"前年実績なし",E12/I12)) -> 0.98749271 | K12: =IF($B12="","",E12-I12) -> -14160
A13: =IF($B13="","","アルチビオ") -> アルチビオ | B13: =IFERROR(INDEX(店舗マスタ!$B$5:$B$304,MATCH("アルチビオ|9",店舗マスタ!$L$5:$L$304,0)),"") -> 32674400 | C13: =IF($B13="","",INDEX(店舗マスタ!$C$5:$C$304,MATCH($B13,店舗マスタ!$B$5:$B$304,0))) -> 伊勢丹浦和店 | D13: =IF($B13="","",INDEX(店舗マスタ!$D$5:$D$304,MATCH($B13,店舗マスタ!$B$5:$B$304,0))) -> アルチビオ | E13: =IF($B13="","",INDEX(店舗マスタ!$G$5:$G$304,MATCH($B13,店舗マスタ!$B$5:$B$304,0))) -> 469470 | F13: =IF($B13="","",INDEX(店舗マスタ!$H$5:$H$304,MATCH($B13,店舗マスタ!$B$5:$B$304,0))) -> 1100000 | G13: =IF($B13="","",IF(F13=0,"-",E13/F13)) -> 0.42679091 | H13: =IF($B13="","",E13-F13) -> -630530 | I13: =IF($B13="","",INDEX(店舗マスタ!$I$5:$I$304,MATCH($B13,店舗マスタ!$B$5:$B$304,0))) -> 1083300 | J13: =IF($B13="","",IF(I13=0,"前年実績なし",E13/I13)) -> 0.43337026 | K13: =IF($B13="","",E13-I13) -> -613830
A14: =IF($B14="","","アルチビオ") -> アルチビオ | B14: =IFERROR(INDEX(店舗マスタ!$B$5:$B$304,MATCH("アルチビオ|10",店舗マスタ!$L$5:$L$304,0)),"") -> 32674900 | C14: =IF($B14="","",INDEX(店舗マスタ!$C$5:$C$304,MATCH($B14,店舗マスタ!$B$5:$B$304,0))) -> 松屋銀座本店 | D14: =IF($B14="","",INDEX(店舗マスタ!$D$5:$D$304,MATCH($B14,店舗マスタ!$B$5:$B$304,0))) -> アルチビオ | E14: =IF($B14="","",INDEX(店舗マスタ!$G$5:$G$304,MATCH($B14,店舗マスタ!$B$5:$B$304,0))) -> 1425313 | F14: =IF($B14="","",INDEX(店舗マスタ!$H$5:$H$304,MATCH($B14,店舗マスタ!$B$5:$B$304,0))) -> 2512000 | G14: =IF($B14="","",IF(F14=0,"-",E14/F14)) -> 0.56740167 | H14: =IF($B14="","",E14-F14) -> -1086687 | I14: =IF($B14="","",INDEX(店舗マスタ!$I$5:$I$304,MATCH($B14,店舗マスタ!$B$5:$B$304,0))) -> 1955945 | J14: =IF($B14="","",IF(I14=0,"前年実績なし",E14/I14)) -> 0.72870812 | K14: =IF($B14="","",E14-I14) -> -530632
A15: =IF($B15="","","アルチビオ") -> アルチビオ | B15: =IFERROR(INDEX(店舗マスタ!$B$5:$B$304,MATCH("アルチビオ|11",店舗マスタ!$L$5:$L$304,0)),"") -> 32680600 | C15: =IF($B15="","",INDEX(店舗マスタ!$C$5:$C$304,MATCH($B15,店舗マスタ!$B$5:$B$304,0))) -> 那須ガーデンアウトレット店 | D15: =IF($B15="","",INDEX(店舗マスタ!$D$5:$D$304,MATCH($B15,店舗マスタ!$B$5:$B$304,0))) -> アルチビオ | E15: =IF($B15="","",INDEX(店舗マスタ!$G$5:$G$304,MATCH($B15,店舗マスタ!$B$5:$B$304,0))) -> 1066595 | F15: =IF($B15="","",INDEX(店舗マスタ!$H$5:$H$304,MATCH($B15,店舗マスタ!$B$5:$B$304,0))) -> 2600000 | G15: =IF($B15="","",IF(F15=0,"-",E15/F15)) -> 0.41022885 | H15: =IF($B15="","",E15-F15) -> -1533405 | I15: =IF($B15="","",INDEX(店舗マスタ!$I$5:$I$304,MATCH($B15,店舗マスタ!$B$5:$B$304,0))) -> 1845195 | J15: =IF($B15="","",IF(I15=0,"前年実績なし",E15/I15)) -> 0.57803918 | K15: =IF($B15="","",E15-I15) -> -778600
A16: =IF($B16="","","アルチビオ") | B16: =IFERROR(INDEX(店舗マスタ!$B$5:$B$304,MATCH("アルチビオ|12",店舗マスタ!$L$5:$L$304,0)),"") | C16: =IF($B16="","",INDEX(店舗マスタ!$C$5:$C$304,MATCH($B16,店舗マスタ!$B$5:$B$304,0))) | D16: =IF($B16="","",INDEX(店舗マスタ!$D$5:$D$304,MATCH($B16,店舗マスタ!$B$5:$B$304,0))) | E16: =IF($B16="","",INDEX(店舗マスタ!$G$5:$G$304,MATCH($B16,店舗マスタ!$B$5:$B$304,0))) | F16: =IF($B16="","",INDEX(店舗マスタ!$H$5:$H$304,MATCH($B16,店舗マスタ!$B$5:$B$304,0))) | G16: =IF($B16="","",IF(F16=0,"-",E16/F16)) | H16: =IF($B16="","",E16-F16) | I16: =IF($B16="","",INDEX(店舗マスタ!$I$5:$I$304,MATCH($B16,店舗マスタ!$B$5:$B$304,0))) | J16: =IF($B16="","",IF(I16=0,"前年実績なし",E16/I16)) | K16: =IF($B16="","",E16-I16)
